Workbook

Sheet Master
A1: PitchNo | B1: Date | C1: Time | D1: Pitcher | E1: Pitch Type | F1: Velocity | G1: SpinRate | H1: Ball/Strike | I1: Sw/Miss/Outcome | J1: Batter | K1: ExitSpeed | L1: Angle | M1: Direction | N1: BatSpeed | O1: HitSpinRate | P1: Distance | Q1: SmashFactor | R1: PotSmashFactor | S1: PotExitSpeed | T1: SquaredUp
A2: 14 | B2: 46193 | C2: 0.80300926 | D2: Gabriel Esteban | E2: SL | F2: 75.826954 | G2: 2359.8291 | H2: 1 | I2: Yes | J2: Aidan Young | N2: 70.690123
A3: 15 | B3: 46193 | C3: 0.80321759 | D3: Gabriel Esteban | E3: FB | F3: 83.131752 | G3: 2265.6592 | H3: 0 | J3: Aidan Young
A4: 16 | B4: 46193 | C4: 0.8034375 | D4: Gabriel Esteban | E4: FB | F4: 85.116757 | G4: 2263.6328 | H4: 0 | J4: Aidan Young
A5: 17 | B5: 46193 | C5: 0.80373843 | D5: Gabriel Esteban | E5: FB | F5: 87.72107 | G5: 1157.3105 | H5: 1 | I5: Foul | J5: Aidan Young | N5: 67.093804
A6: 18 | B6: 46193 | C6: 0.80400463 | D6: Gabriel Esteban | E6: SL | F6: 73.857842 | G6: 2109.9846 | H6: 1 | I6: bK | J6: Aidan Young
A7: 56 | B7: 46193 | C7: 0.81756944 | D7: Gabriel Esteban | E7: FB | F7: 80.575076 | G7: 2106.9888 | H7: 1 | J7: Aidan Young
A8: 57 | B8: 46193 | C8: 0.81774306 | D8: Gabriel Esteban | E8: FB | F8: 82.702991 | G8: 1916.3033 | H8: 0 | J8: Aidan Young
A9: 58 | B9: 46193 | C9: 0.81795139 | D9: Gabriel Esteban | E9: FB | F9: 83.274675 | G9: 2153.8503 | H9: 1 | I9: In Play | J9: Aidan Young | K9: 96.40483 | L9: -10.951885 | M9: -8.8998146 | N9: 69.622466 | O9: 1112.8253 | P9: 15 | Q9: 1.3846799 | R9: 1.4863824 | S9: 103.4856 | T9: 0.93157722
A10: 70 | B10: 46193 | C10: 0.83362269 | D10: Reagan Samples | E10: SL | F10: 74.874159 | G10: 1164.7894 | H10: 0 | J10: Aidan Young
A11: 71 | B11: 46193 | C11: 0.83384259 | D11: Reagan Samples | E11: SP | F11: 71.888722 | G11: 372.69415 | H11: 1 | I11: Yes | J11: Aidan Young | N11: 69.453891
A12: 72 | B12: 46193 | C12: 0.8341088 | D12: Reagan Samples | E12: SL | F12: 73.174996 | G12: 2152.7905 | H12: 1 | I12: In Play | J12: Aidan Young | K12: 84.835361 | L12: -7.1139536 | M12: -28.276945 | N12: 67.824308 | O12: 2291.5283 | P12: 20 | Q12: 1.2508105 | R12: 1.4561263 | S12: 98.760762 | T12: 0.85899864
A13: 106 | B13: 46193 | C13: 0.84975694 | D13: Anthony Wilson | F13: 72.523919 | G13: 1249.9954 | J13: Aidan Young
A14: 107 | B14: 46193 | C14: 0.85002315 | D14: Anthony Wilson | F14: 71.078841 | G14: 1245.3386 | J14: Aidan Young
A15: 108 | B15: 46193 | C15: 0.85023148 | D15: Anthony Wilson | F15: 70.729482 | G15: 2371.0532 | J15: Aidan Young
A16: 109 | B16: 46193 | C16: 0.85041667 | D16: Anthony Wilson | F16: 70.25308 | G16: 2393.1138 | I16: K | J16: Aidan Young | N16: 43.830123
A17: 110 | B17: 46193 | C17: 0.85069444 | D17: Anthony Wilson | E17: FB | F17: 83.084111 | G17: 1158.9977 | J17: Aidan Young
A18: 139 | B18: 46193 | C18: 0.86023148 | D18: Anthony Wilson | E18: FB | F18: 85.497873 | G18: 1094.5211 | H18: 1 | J18: Aidan Young
A19: 140 | B19: 46193 | C19: 0.86041667 | D19: Anthony Wilson | E19: SL | F19: 77.367314 | G19: 1724.5892 | H19: 0 | J19: Aidan Young
A20: 141 | B20: 46193 | C20: 0.86060185 | D20: Anthony Wilson | E20: CB | F20: 72.730363 | G20: 2419.2544 | H20: 1 | J20: Aidan Young
A21: 142 | B21: 46193 | C21: 0.86078704 | D21: Anthony Wilson | E21: SL | F21: 74.890039 | G21: 1105.9824 | H21: 0 | J21: Aidan Young
A22: 143 | B22: 46193 | C22: 0.86100694 | D22: Anthony Wilson | E22: FB | F22: 85.545514 | G22: 2125.25 | H22: 1 | I22: bK | J22: Aidan Young
A23: 178 | B23: 46193 | C23: 0.88253472 | D23: Drew Craig | E23: FB | F23: 76.779758 | G23: 2150.9719 | H23: 0 | J23: Aidan Young
A24: 179 | B24: 46193 | C24: 0.88269676 | D24: Drew Craig | E24: SL | F24: 73.047962 | G24: 2337.0591 | H24: 0 | J24: Aidan Young
A25: 180 | B25: 46193 | C25: 0.88296296 | D25: Drew Craig | E25: FB | F25: 76.414518 | G25: 2101.2842 | H25: 1 | I25: Foul | J25: Aidan Young | K25: 86.997759 | L25: 20.655521 | M25: -42.985615 | N25: 66.92523 | O25: 2953.1411 | P25: 254 | Q25: 1.2999247 | R25: 1.4723643 | S25: 98.538326 | T25: 0.88288246
A26: 181 | B26: 46193 | C26: 0.88321759 | D26: Drew Craig | E26: SL | F26: 70.475401 | G26: 1212.6408 | H26: 1 | J26: Aidan Young
A27: 182 | B27: 46193 | C27: 0.88350694 | D27: Drew Craig | E27: FB | F27: 78.002519 | G27: 2182.9226 | H27: 0 | J27: Aidan Young
A28: 183 | B28: 46193 | C28: 0.88376157 | D28: Drew Craig | E28: SL | F28: 72.666842 | G28: 1280.4403 | H28: 0 | I28: BB | J28: Aidan Young
A29: 198 | B29: 46197 | C29: 0.57978009 | D29: Sebastian Garcia | E29: FB | F29: 87.085873 | G29: 1085.9849 | H29: 1 | I29: Foul | J29: Aidan Young | K29: 80.17793 | L29: 41.245014 | M29: 42.189346 | N29: 65.576608 | P29: 291 | Q29: 1.2226605 | R29: 1.5126283 | S29: 99.193038 | T29: 0.808302
A30: 199 | B30: 46197 | C30: 0.58012731 | D30: Sebastian Garcia | E30: FB | F30: 86.768275 | G30: 1793.8013 | H30: 1 | J30: Aidan Young
A31: 200 | B31: 46197 | C31: 0.58037037 | D31: Sebastian Garcia | E31: SL | F31: 77.796075 | G31: 2209.9841 | H31: 0 | J31: Aidan Young
A32: 201 | B32: 46197 | C32: 0.58063657 | D32: Sebastian Garcia | E32: FB | F32: 84.910317 | G32: 1925.6492 | H32: 1 | I32: Foul | J32: Aidan Young | N32: 66.756652
A33: 202 | B33: 46197 | C33: 0.58096065 | D33: Sebastian Garcia | E33: SL | F33: 75.906356 | G33: 2114.1 | H33: 1 | I33: K | J33: Aidan Young | N33: 37.14322
A34: 236 | B34: 46197 | C34: 0.59570602 | D34: Sebastian Garcia | E34: FB | F34: 83.639915 | G34: 1955.8721 | H34: 0 | J34: Aidan Young
A35: 237 | B35: 46197 | C35: 0.59594907 | D35: Sebastian Garcia | E35: FB | F35: 83.465227 | G35: 2013.8984 | H35: 0 | J35: Aidan Young
A36: 238 | B36: 46197 | C36: 0.59616898 | D36: Sebastian Garcia | E36: SL | F36: 73.873722 | G36: 1104.5194 | H36: 0 | J36: Aidan Young
A37: 239 | B37: 46197 | C37: 0.59638889 | D37: Sebastian Garcia | E37: FB | F37: 83.576393 | G37: 1928.0399 | H37: 0 | J37: Aidan Young
A38: 240 | B38: 46197 | C38: 0.59659722 | D38: Sebastian Garcia | E38: FB | F38: 83.338196 | G38: 1889.4633 | H38: 1 | I38: Yes | J38: Aidan Young | L38: -59.820744 | M38: -6.4822268 | N38: 60.406902 | P38: 7
A39: 241 | B39: 46197 | C39: 0.59688657 | D39: Sebastian Garcia | E39: FB | F39: 87.085873 | G39: 1861.2362 | H39: 1 | J39: Aidan Young
A40: 242 | B40: 46197 | C40: 0.59706019 | D40: Sebastian Garcia | E40: FB | F40: 84.084556 | G40: 2056.9067 | H40: 0 | J40: Aidan Young
...

Sheet Totals
B2: 2026 Shepherds Pitching Stat Sheet
B3: # | C3: Name | D3: G | E3: IP | F3: TP | G3: B | H3: S | I3: S% | J3: P/IP | K3: P/PA | L3: BF | M3: H | N3: BB | O3: BB% | P3: BB/9 | Q3: HBP | R3: WHIP | S3: K | T3: K/9 | U3: K% | V3: K/BB | W3: K%-BB% | X3: BAA | Y3: FPS | Z3: FPS% | AA3: 0.66666667 | AB3: 2/3% | AC3: <3P | AD3: <3P% | AE3: 3BC | AF3: 3BC% | AG3: 3BC-BB% | AH3: TFB | AI3: FB K | AJ3: S/M | AK3: TSW | AL3: TCB | AM3: CB K | AN3: S/M | AO3: TSW | AP3: TCH | AQ3: CH K | AR3: S/M | AS3: TSW | AT3: TO | AU3: O K | AV3: S/M | AW3: TSW | AX3: SW/M% | AY3: FB K% | AZ3: FB S/M% | BA3: CB K% | BB3: CB S/M% | BC3: CH K% | BD3: CH S/M% | BE3: O K% | BF3: O S/M% | BG3: FB USG | BH3: CB USG | BI3: CH USG | BJ3: O USG
C4: Andrew Craig | D4: 6 | E4: =SUM(Craig!C5:M5) -> 11 | F4: =SUM(Craig!C6:M6) -> 221 | G4: =SUM(Craig!C7:M7) -> 126 | H4: =SUM(Craig!C8:M8) -> 95 | I4: =H4/F4 -> 0.42986425 | J4: =F4/E4 -> 20.090909 | K4: =F4/L4 -> 4.25 | L4: =SUM(Craig!C12:M12) -> 52 | M4: =SUM(Craig!C13:M13) -> 8 | N4: =SUM(Craig!C14:M14) -> 16 | O4: =N4/L4 -> 0.30769231 | P4: =(N4*9)/E4 -> 13.090909 | Q4: =SUM(Craig!C17:M17) -> 2 | R4: =(M4+N4)/E4 -> 2.1818182 | S4: =SUM(Craig!C19:M20) -> 10 | T4: =(S4*9)/E4 -> 8.1818182 | U4: =S4/L4 -> 0.19230769 | V4: =S4/N4 -> 0.625 | W4: =U4-O4 -> -0.11538462 | X4: =M4/(L4-N4-Q4) -> 0.23529412 | Y4: =SUM(Craig!C26:M26) -> 19 | Z4: =Y4/L4 -> 0.36538462 | AA4: =SUM(Craig!C28:M28) -> 8 | AB4: =AA4/L4 -> 0.15384615 | AC4: =SUM(Craig!C30:M30) -> 16 | AD4: =AC4/L4 -> 0.30769231 | AE4: =SUM(Craig!C32:M32) -> 22 | AF4: =AE4/L4 -> 0.42307692 | AG4: =N4/AE4 -> 0.72727273 | AH4: =SUM(Craig!C34:M34) -> 108 | AI4: =SUM(Craig!C35:M35) -> 31 | AJ4: =SUM(Craig!C51:M51) -> 6 | AK4: =SUM(Craig!C50:M50) -> 38 | AL4: =SUM(Craig!C38:M38) -> 0 | AM4: =SUM(Craig!C39:M39) -> 0 | AN4: =SUM(Craig!C54:M54) -> 0 | AO4: =SUM(Craig!C53:M53) -> 0 | AP4: =SUM(Craig!C42:M42) -> 12 | AQ4: =SUM(Craig!C43:M43) -> 4 | AR4: =SUM(Craig!C57:M57) -> 3 | AS4: =SUM(Craig!C56:M56) -> 4 | AT4: =SUM(Craig!C46:M46) -> 101 | AU4: =SUM(Craig!C47:M47) -> 39 | AV4: =SUM(Craig!C60:M60) -> 15 | AW4: =SUM(Craig!C59:M59) -> 38 | AX4: =(SUM(AJ4+AN4+AR4+AV4)/SUM(AK4+AO4+AS4+AW4)) -> 0.3 | AY4: =AI4/AH4 -> 0.28703704 | AZ4: =AJ4/AK4 -> 0.15789474 | BA4: =AM4/AL4 -> #DIV/0! | BB4: =AN4/AO4 -> #DIV/0! | BC4: =AQ4/AP4 -> 0.33333333 | BD4: =AR4/AS4 -> 0.75 | BE4: =AU4/AT4 -> 0.38613861 | BF4: =AV4/AW4 -> 0.39473684 | BG4: =AH4/F4 -> 0.48868778 | BH4: =AL4/F4 -> 0 | BI4: =AP4/F4 -> 0.054298643 | BJ4: =AT4/F4 -> 0.45701357 | BK4: =SUM(BG4:BJ4) -> 1
C5: Gabriel Esteban | D5: 6 | E5: =SUM(Esteban!C5:M5) -> 12.333333 | F5: =SUM(Esteban!C6:M6) -> 319 | G5: =SUM(Esteban!C7:M7) -> 143 | H5: =SUM(Esteban!C8:M8) -> 176 | I5: =H5/F5 -> 0.55172414 | J5: =F5/E5 -> 25.864865 | K5: =F5/L5 -> 4.761194 | L5: =SUM(Esteban!C12:M12) -> 67 | M5: =SUM(Esteban!C13:M13) -> 13 | N5: =SUM(Esteban!C14:M14) -> 13 | O5: =N5/L5 -> 0.19402985 | P5: =(N5*9)/E5 -> 9.4864865 | Q5: =SUM(Esteban!C17:M17) -> 2 | R5: =(M5+N5)/E5 -> 2.1081081 | S5: =SUM(Esteban!C19:M20) -> 14 | T5: =(S5*9)/E5 -> 10.216216 | U5: =S5/L5 -> 0.20895522 | V5: =S5/N5 -> 1.0769231 | W5: =U5-O5 -> 0.014925373 | X5: =M5/(L5-N5-Q5) -> 0.25 | Y5: =SUM(Esteban!C26:M26) -> 23 | Z5: =Y5/L5 -> 0.34328358 | AA5: =SUM(Esteban!C28:M28) -> 23 | AB5: =AA5/L5 -> 0.34328358 | AC5: =SUM(Esteban!C30:M30) -> 17 | AD5: =AC5/L5 -> 0.25373134 | AE5: =SUM(Esteban!C32:M32) -> 29 | AF5: =AE5/L5 -> 0.43283582 | AG5: =N5/AE5 -> 0.44827586 | AH5: =SUM(Esteban!C34:M34) -> 127 | AI5: =SUM(Esteban!C35:M35) -> 76 | AJ5: =SUM(Esteban!C51:M51) -> 19 | AK5: =SUM(Esteban!C50:M50) -> 66 | AL5: =SUM(Esteban!C38:M38) -> 103 | AM5: =SUM(Esteban!C39:M39) -> 48 | AN5: =SUM(Esteban!C54:M54) -> 12 | AO5: =SUM(Esteban!C53:M53) -> 34 | AP5: =SUM(Esteban!C42:M42) -> 14 | AQ5: =SUM(Esteban!C43:M43) -> 7 | AR5: =SUM(Esteban!C57:M57) -> 0 | AS5: =SUM(Esteban!C56:M56) -> 6 | AT5: =SUM(Esteban!C46:M46) -> 56 | AU5: =SUM(Esteban!C47:M47) -> 26 | AV5: =SUM(Esteban!C60:M60) -> 6 | AW5: =SUM(Esteban!C59:M59) -> 23 | AX5: =(SUM(AJ5+AN5+AR5+AV5)/SUM(AK5+AO5+AS5+AW5)) -> 0.28682171 | AY5: =AI5/AH5 -> 0.5984252 | AZ5: =AJ5/AK5 -> 0.28787879 | BA5: =AM5/AL5 -> 0.46601942 | BB5: =AN5/AO5 -> 0.35294118 | BC5: =AQ5/AP5 -> 0.5 | BD5: =AR5/AS5 -> 0 | BE5: =AU5/AT5 -> 0.46428571 | BF5: =AV5/AW5 -> 0.26086957 | BG5: =AH5/F5 -> 0.39811912 | BH5: =AL5/F5 -> 0.32288401 | BI5: =AP5/F5 -> 0.043887147 | BJ5: =AT5/F5 -> 0.17554859 | BK5: =SUM(BG5:BJ5) -> 0.94043887
C6: Sebastian Garcia | D6: 8 | E6: =SUM(Garcia!C5:M5) -> 15 | F6: =SUM(Garcia!C6:M6) -> 288 | G6: =SUM(Garcia!C7:M7) -> 117 | H6: =SUM(Garcia!C8:M8) -> 171 | I6: =H6/F6 -> 0.59375 | J6: =F6/E6 -> 19.2 | K6: =F6/L6 -> 4.2985075 | L6: =SUM(Garcia!C12:M12) -> 67 | M6: =SUM(Garcia!C13:M13) -> 11 | N6: =SUM(Garcia!C14:M14) -> 11 | O6: =N6/L6 -> 0.1641791 | P6: =(N6*9)/E6 -> 6.6 | Q6: =SUM(Garcia!C17:M17) -> 0 | R6: =(M6+N6)/E6 -> 1.4666667 | S6: =SUM(Garcia!C19:M20) -> 22 | T6: =(S6*9)/E6 -> 13.2 | U6: =S6/L6 -> 0.32835821 | V6: =S6/N6 -> 2 | W6: =U6-O6 -> 0.1641791 | X6: =M6/(L6-N6-Q6) -> 0.19642857 | Y6: =SUM(Garcia!C26:M26) -> 36 | Z6: =Y6/L6 -> 0.53731343 | AA6: =SUM(Garcia!C28:M28) -> 32 | AB6: =AA6/L6 -> 0.47761194 | AC6: =SUM(Garcia!C30:M30) -> 26 | AD6: =AC6/L6 -> 0.3880597 | AE6: =SUM(Garcia!C32:M32) -> 17 | AF6: =AE6/L6 -> 0.25373134 | AG6: =N6/AE6 -> 0.64705882 | AH6: =SUM(Garcia!C34:M34) -> 156 | AI6: =SUM(Garcia!C35:M35) -> 97 | AJ6: =SUM(Garcia!C51:M51) -> 18 | AK6: =SUM(Garcia!C50:M50) -> 77 | AL6: =SUM(Garcia!C38:M38) -> 0 | AM6: =SUM(Garcia!C39:M39) -> 0 | AN6: =SUM(Garcia!C54:M54) -> 0 | AO6: =SUM(Garcia!C53:M53) -> 0 | AP6: =SUM(Garcia!C42:M42) -> 41 | AQ6: =SUM(Garcia!C43:M43) -> 26 | AR6: =SUM(Garcia!C57:M57) -> 8 | AS6: =SUM(Garcia!C56:M56) -> 24 | AT6: =SUM(Garcia!C46:M46) -> 91 | AU6: =SUM(Garcia!C47:M47) -> 48 | AV6: =SUM(Garcia!C60:M60) -> 18 | AW6: =SUM(Garcia!C59:M59) -> 32 | AX6: =(SUM(AJ6+AN6+AR6+AV6)/SUM(AK6+AO6+AS6+AW6)) -> 0.33082707 | AY6: =AI6/AH6 -> 0.62179487 | AZ6: =AJ6/AK6 -> 0.23376623 | BA6: =AM6/AL6 -> #DIV/0! | BB6: =AN6/AO6 -> #DIV/0! | BC6: =AQ6/AP6 -> 0.63414634 | BD6: =AR6/AS6 -> 0.33333333 | BE6: =AU6/AT6 -> 0.52747253 | BF6: =AV6/AW6 -> 0.5625 | BG6: =AH6/F6 -> 0.54166667 | BH6: =AL6/F6 -> 0 | BI6: =AP6/F6 -> 0.14236111 | BJ6: =AT6/F6 -> 0.31597222 | BK6: =SUM(BG6:BJ6) -> 1
C7: Jackson Orr | D7: 5 | E7: =SUM('Orr (P)'!C5:M5) -> 6.6666667 | F7: =SUM('Orr (P)'!C6:M6) -> 172 | G7: =SUM('Orr (P)'!C7:M7) -> 85 | H7: =SUM('Orr (P)'!C8:M8) -> 84 | I7: =H7/F7 -> 0.48837209 | J7: =F7/E7 -> 25.8 | K7: =F7/L7 -> 4.7777778 | L7: =SUM('Orr (P)'!C12:M12) -> 36 | M7: =SUM('Orr (P)'!C13:M13) -> 7 | N7: =SUM('Orr (P)'!C14:M14) -> 10 | O7: =N7/L7 -> 0.27777778 | P7: =(N7*9)/E7 -> 13.5 | Q7: =SUM('Orr (P)'!C17:M17) -> 1 | R7: =(M7+N7)/E7 -> 2.55 | S7: =SUM('Orr (P)'!C19:M20) -> 10 | T7: =(S7*9)/E7 -> 13.5 | U7: =S7/L7 -> 0.27777778 | V7: =S7/N7 -> 1 | W7: =U7-O7 -> 0 | X7: =M7/(L7-N7-Q7) -> 0.28 | Y7: =SUM('Orr (P)'!C26:M26) -> 16 | Z7: =Y7/L7 -> 0.44444444 | AA7: =SUM('Orr (P)'!C28:M28) -> 12 | AB7: =AA7/L7 -> 0.33333333 | AC7: =SUM('Orr (P)'!C30:M30) -> 9 | AD7: =AC7/L7 -> 0.25 | AE7: =SUM('Orr (P)'!C32:M32) -> 17 | AF7: =AE7/L7 -> 0.47222222 | AG7: =N7/AE7 -> 0.58823529 | AH7: =SUM('Orr (P)'!C34:M34) -> 102 | AI7: =SUM('Orr (P)'!C35:M35) -> 58 | AJ7: =SUM('Orr (P)'!C51:M51) -> 11 | AK7: =SUM('Orr (P)'!C50:M50) -> 40 | AL7: =SUM('Orr (P)'!C38:M38) -> 18 | AM7: =SUM('Orr (P)'!C39:M39) -> 6 | AN7: =SUM('Orr (P)'!C54:M54) -> 1 | AO7: =SUM('Orr (P)'!C53:M53) -> 2 | AP7: =SUM('Orr (P)'!C42:M42) -> 11 | AQ7: =SUM('Orr (P)'!C43:M43) -> 3 | AR7: =SUM('Orr (P)'!C57:M57) -> 1 | AS7: =SUM('Orr (P)'!C56:M56) -> 2 | AT7: =SUM('Orr (P)'!C46:M46) -> 41 | AU7: =SUM('Orr (P)'!C47:M47) -> 17 | AV7: =SUM('Orr (P)'!C60:M60) -> 9 | AW7: =SUM('Orr (P)'!C59:M59) -> 12 | AX7: =(SUM(AJ7+AN7+AR7+AV7)/SUM(AK7+AO7+AS7+AW7)) -> 0.39285714 | AY7: =AI7/AH7 -> 0.56862745 | AZ7: =AJ7/AK7 -> 0.275 | BA7: =AM7/AL7 -> 0.33333333 | BB7: =AN7/AO7 -> 0.5 | BC7: =AQ7/AP7 -> 0.27272727 | BD7: =AR7/AS7 -> 0.5 | BE7: =AU7/AT7 -> 0.41463415 | BF7: =AV7/AW7 -> 0.75 | BG7: =AH7/F7 -> 0.59302326 | BH7: =AL7/F7 -> 0.10465116 | BI7: =AP7/F7 -> 0.063953488 | BJ7: =AT7/F7 -> 0.23837209 | BK7: =SUM(BG7:BJ7) -> 1
C8: Reagan Samples | D8: 5 | E8: =SUM('Samples (P)'!C5:M5) -> 15 | F8: =SUM('Samples (P)'!C6:M6) -> 258 | G8: =SUM('Samples (P)'!C7:M7) -> 105 | H8: =SUM('Samples (P)'!C8:M8) -> 153 | I8: =H8/F8 -> 0.59302326 | J8: =F8/E8 -> 17.2 | K8: =F8/L8 -> 4.0952381 | L8: =SUM('Samples (P)'!C12:M12) -> 63 | M8: =SUM('Samples (P)'!C13:M13) -> 12 | N8: =SUM('Samples (P)'!C14:M14) -> 8 | O8: =N8/L8 -> 0.12698413 | P8: =(N8*9)/E8 -> 4.8 | Q8: =SUM('Samples (P)'!C17:M17) -> 1 | R8: =(M8+N8)/E8 -> 1.3333333 | S8: =SUM('Samples (P)'!C19:M20) -> 13 | T8: =(S8*9)/E8 -> 7.8 | U8: =S8/L8 -> 0.20634921 | V8: =S8/N8 -> 1.625 | W8: =U8-O8 -> 0.079365079 | X8: =M8/(L8-N8-Q8) -> 0.22222222 | Y8: =SUM('Samples (P)'!C26:M26) -> 34 | Z8: =Y8/L8 -> 0.53968254 | AA8: =SUM('Samples (P)'!C28:M28) -> 33 | AB8: =AA8/L8 -> 0.52380952 | AC8: =SUM('Samples (P)'!C30:M30) -> 25 | AD8: =AC8/L8 -> 0.3968254 | AE8: =SUM('Samples (P)'!C32:M32) -> 18 | AF8: =AE8/L8 -> 0.28571429 | AG8: =N8/AE8 -> 0.44444444 | AH8: =SUM('Samples (P)'!C34:M34) -> 113 | AI8: =SUM('Samples (P)'!C35:M35) -> 72 | AJ8: =SUM('Samples (P)'!C51:M51) -> 10 | AK8: =SUM('Samples (P)'!C50:M50) -> 52 | AL8: =SUM('Samples (P)'!C38:M38) -> 95 | AM8: =SUM('Samples (P)'!C39:M39) -> 52 | AN8: =SUM('Samples (P)'!C54:M54) -> 17 | AO8: =SUM('Samples (P)'!C53:M53) -> 43 | AP8: =SUM('Samples (P)'!C42:M42) -> 16 | AQ8: =SUM('Samples (P)'!C43:M43) -> 13 | AR8: =SUM('Samples (P)'!C57:M57) -> 4 | AS8: =SUM('Samples (P)'!C56:M56) -> 13 | AT8: =SUM('Samples (P)'!C46:M46) -> 34 | AU8: =SUM('Samples (P)'!C47:M47) -> 16 | AV8: =SUM('Samples (P)'!C60:M60) -> 4 | AW8: =SUM('Samples (P)'!C59:M59) -> 13 | AX8: =(SUM(AJ8+AN8+AR8+AV8)/SUM(AK8+AO8+AS8+AW8)) -> 0.2892562 | AY8: =AI8/AH8 -> 0.63716814 | AZ8: =AJ8/AK8 -> 0.19230769 | BA8: =AM8/AL8 -> 0.54736842 | BB8: =AN8/AO8 -> 0.39534884 | BC8: =AQ8/AP8 -> 0.8125 | BD8: =AR8/AS8 -> 0.30769231 | BE8: =AU8/AT8 -> 0.47058824 | BF8: =AV8/AW8 -> 0.30769231 | BG8: =AH8/F8 -> 0.4379845 | BH8: =AL8/F8 -> 0.36821705 | BI8: =AP8/F8 -> 0.062015504 | BJ8: =AT8/F8 -> 0.13178295 | BK8: =SUM(BG8:BJ8) -> 1
C9: Jonathon Van Ness | D9: 0 | E9: =SUM('Van Ness'!C5:M5) -> 0 | F9: =SUM(Craig!C6:M6) -> 221 | G9: =SUM(Craig!C7:M7) -> 126 | H9: =SUM(Craig!C8:M8) -> 95 | I9: =H9/F9 -> 0.42986425 | J9: =F9/E9 -> #DIV/0! | K9: =F9/L9 -> 4.25 | L9: =SUM(Craig!C12:M12) -> 52 | M9: =SUM(Craig!C13:M13) -> 8 | N9: =SUM(Craig!C14:M14) -> 16 | O9: =N9/L9 -> 0.30769231 | P9: =(N9*9)/E9 -> #DIV/0! | Q9: =SUM(Craig!C17:M17) -> 2 | R9: =(M9+N9)/E9 -> #DIV/0! | S9: =SUM(Craig!C19:M20) -> 10 | T9: =(S9*9)/E9 -> #DIV/0! | U9: =S9/L9 -> 0.19230769 | V9: =S9/N9 -> 0.625 | W9: =U9-O9 -> -0.11538462 | X9: =M9/(L9-N9-Q9) -> 0.23529412 | Y9: =SUM(Craig!C26:M26) -> 19 | Z9: =Y9/L9 -> 0.36538462 | AA9: =SUM(Craig!C28:M28) -> 8 | AB9: =AA9/L9 -> 0.15384615 | AC9: =SUM(Craig!C30:M30) -> 16 | AD9: =AC9/L9 -> 0.30769231 | AE9: =SUM(Craig!C32:M32) -> 22 | AF9: =AE9/L9 -> 0.42307692 | AG9: =N9/AE9 -> 0.72727273 | AH9: =SUM(Craig!C34:M34) -> 108 | AI9: =SUM(Craig!C35:M35) -> 31 | AJ9: =SUM(Craig!C51:M51) -> 6 | AK9: =SUM(Craig!C50:M50) -> 38 | AL9: =SUM(Craig!C38:M38) -> 0 | AM9: =SUM(Craig!C39:M39) -> 0 | AN9: =SUM(Craig!C54:M54) -> 0 | AO9: =SUM(Craig!C53:M53) -> 0 | AP9: =SUM(Craig!C42:M42) -> 12 | AQ9: =SUM(Craig!C43:M43) -> 4 | AR9: =SUM(Craig!C57:M57) -> 3 | AS9: =SUM(Craig!C56:M56) -> 4 | AT9: =SUM(Craig!C46:M46) -> 101 | AU9: =SUM(Craig!C47:M47) -> 39 | AV9: =SUM(Craig!C60:M60) -> 15 | AW9: =SUM(Craig!C59:M59) -> 38 | AX9: =(SUM(AJ9+AN9+AR9+AV9)/SUM(AK9+AO9+AS9+AW9)) -> 0.3 | AY9: =AI9/AH9 -> 0.28703704 | AZ9: =AJ9/AK9 -> 0.15789474 | BA9: =AM9/AL9 -> #DIV/0! | BB9: =AN9/AO9 -> #DIV/0! | BC9: =AQ9/AP9 -> 0.33333333 | BD9: =AR9/AS9 -> 0.75 | BE9: =AU9/AT9 -> 0.38613861 | BF9: =AV9/AW9 -> 0.39473684 | BG9: =AH9/F9 -> 0.48868778 | BH9: =AL9/F9 -> 0 | BI9: =AP9/F9 -> 0.054298643 | BJ9: =AT9/F9 -> 0.45701357 | BK9: =SUM(BG9:BJ9) -> 1
C10: Carter Walsh | D10: 1 | E10: =SUM('Walsh (P)'!C5:M5) -> 1 | F10: =SUM('Walsh (P)'!C6:M6) -> 22 | G10: =SUM('Walsh (P)'!C7:M7) -> 10 | H10: =SUM('Walsh (P)'!C8:M8) -> 12 | I10: =H10/F10 -> 0.54545455 | J10: =F10/E10 -> 22 | K10: =F10/L10 -> 4.4 | L10: =SUM('Walsh (P)'!C12:M12) -> 5 | M10: =SUM('Walsh (P)'!C13:M13) -> 1 | N10: =SUM('Walsh (P)'!C14:M14) -> 1 | O10: =N10/L10 -> 0.2 | P10: =(N10*9)/E10 -> 9 | Q10: =SUM('Walsh (P)'!C17:M17) -> 0 | R10: =(M10+N10)/E10 -> 2 | S10: =SUM('Walsh (P)'!C19:M20) -> 2 | T10: =(S10*9)/E10 -> 18 | U10: =S10/L10 -> 0.4 | V10: =S10/N10 -> 2 | W10: =U10-O10 -> 0.2 | X10: =M10/(L10-N10-Q10) -> 0.25 | Y10: =SUM('Walsh (P)'!C26:M26) -> 2 | Z10: =Y10/L10 -> 0.4 | AA10: =SUM('Walsh (P)'!C28:M28) -> 2 | AB10: =AA10/L10 -> 0.4 | AC10: =SUM('Walsh (P)'!C30:M30) -> 1 | AD10: =AC10/L10 -> 0.2 | AE10: =SUM('Walsh (P)'!C32:M32) -> 2 | AF10: =AE10/L10 -> 0.4 | AG10: =N10/AE10 -> 0.5 | AH10: =SUM('Walsh (P)'!C34:M34) -> 12 | AI10: =SUM('Walsh (P)'!C35:M35) -> 6 | AJ10: =SUM('Walsh (P)'!C51:M51) -> 2 | AK10: =SUM('Walsh (P)'!C50:M50) -> 4 | AL10: =SUM('Walsh (P)'!C38:M38) -> 3 | AM10: =SUM('Walsh (P)'!C39:M39) -> 3 | AN10: =SUM('Walsh (P)'!C54:M54) -> 0 | AO10: =SUM('Walsh (P)'!C53:M53) -> 1 | AP10: =SUM('Walsh (P)'!C42:M42) -> 3 | AQ10: =SUM('Walsh (P)'!C43:M43) -> 1 | AR10: =SUM('Walsh (P)'!C57:M57) -> 0 | AS10: =SUM('Walsh (P)'!C56:M56) -> 1 | AT10: =SUM('Walsh (P)'!C46:M46) -> 4 | AU10: =SUM('Walsh (P)'!C47:M47) -> 2 | AV10: =SUM('Walsh (P)'!C60:M60) -> 1 | AW10: =SUM('Walsh (P)'!C59:M59) -> 1 | AX10: =(SUM(AJ10+AN10+AR10+AV10)/SUM(AK10+AO10+AS10+AW10)) -> 0.42857143 | AY10: =AI10/AH10 -> 0.5 | AZ10: =AJ10/AK10 -> 0.5 | BA10: =AM10/AL10 -> 1 | BB10: =AN10/AO10 -> 0 | BC10: =AQ10/AP10 -> 0.33333333 | BD10: =AR10/AS10 -> 0 | BE10: =AU10/AT10 -> 0.5 | BF10: =AV10/AW10 -> 1 | BG10: =AH10/F10 -> 0.54545455 | BH10: =AL10/F10 -> 0.13636364 | BI10: =AP10/F10 -> 0.13636364 | BJ10: =AT10/F10 -> 0.18181818 | BK10: =SUM(BG10:BJ10) -> 1
B11: TOTALS | D11: =SUM(D4:D10) -> 31 | E11: =SUM(E4:E10) -> 61 | F11: =SUM(F4:F10) -> 1501 | G11: =SUM(G4:G10) -> 712 | H11: =SUM(H4:H10) -> 786 | I11: =H11/F11 -> 0.5236509 | J11: =F11/E11 -> 24.606557 | K11: =F11/L11 -> 4.3888889 | L11: =SUM(L4:L10) -> 342 | M11: =SUM(M4:M10) -> 60 | N11: =SUM(N4:N10) -> 75 | O11: =N11/L11 -> 0.21929825 | P11: =(N11*9)/E11 -> 11.065574 | Q11: =SUM(Q4:Q10) -> 8 | R11: =(N11+M11)/E11 -> 2.2131148 | S11: =SUM(S4:S10) -> 81 | T11: =(S11*9)/E11 -> 11.95082 | U11: =S11/L11 -> 0.23684211 | V11: =S11/N11 -> 1.08 | W11: =U11-O11 -> 0.01754386 | X11: =M11/(L11-N11-Q11) -> 0.23166023 | Y11: =SUM(Y4:Y10) -> 149 | Z11: =Y11/L11 -> 0.43567251 | AA11: =SUM(AA4:AA10) -> 118 | AB11: =AA11/L11 -> 0.34502924 | AC11: =SUM(AC4:AC10) -> 110 | AD11: =AC11/L11 -> 0.32163743 | AE11: =SUM(AE4:AE10) -> 127 | AF11: =AE11/L11 -> 0.37134503 | AG11: =N11/AE11 -> 0.59055118 | AH11: =SUM(AH4:AH10) -> 726 | AI11: =SUM(AI4:AI10) -> 371 | AJ11: =SUM(AJ4:AJ10) -> 72 | AK11: =SUM(AK4:AK10) -> 315 | AL11: =SUM(AL4:AL10) -> 219 | AM11: =SUM(AM4:AM10) -> 109 | AN11: =SUM(AN4:AN10) -> 30 | AO11: =SUM(AO4:AO10) -> 80 | ... AW11: =SUM(AW4:AW10) -> 157 | AX11: =(SUM(AJ11+AN11+AR11+AV11)/SUM(AK11+AO11+AS11+AW11)) -> 0.31188119 | AY11: =AI11/AH11 -> 0.51101928 | AZ11: =AJ11/AI11 -> 0.19407008 | BA11: =AM11/AL11 -> 0.49771689 | BB11: =AN11/AM11 -> 0.27522936 | BC11: =AQ11/AP11 -> 0.53211009 | BD11: =AR11/AS11 -> 0.35185185 | BE11: =AU11/AT11 -> 0.43691589 | BF11: =AV11/AW11 -> 0.43312102 | BG11: =AH11/F11 -> 0.48367755 | BH11: =AL11/F11 -> 0.14590273 | BI11: =AP11/F11 -> 0.072618254 | BJ11: =AT11/F11 -> 0.28514324 | BK11: =SUM(BG11:BJ11) -> 0.98734177
C13: Last Updated | D13: 46252 | AH13: =29+4+36 -> 69 | AV13: FB SW/FBK | AX13: =AK11/AI11 -> 0.8490566 | AZ13: CB SW/CBK | BB13: =AO11/AM11 -> 0.73394495 | BD13: CH SW/CHK | BF13: =AS11/AQ11 -> 0.93103448 | BH13: SL SW/SLK | BJ13: =AW11/AU11 -> 0.83957219
B15: 2026 Shepherds Hitting Stat Sheet
B16: # | C16: Name | D16: PA | E16: AB | F16: K | G16: BB | H16: TP | I16: K% | J16: BB% | K16: HBP | L16: P/PA | M16: H | N16: BA | O16: EV90 | P16: Max EV | Q16: BatSpeed90 | R16: Max BatSp | S16: Whiff % | T16: Whiffs | U16: Total Swings | V16: Tot FB | W16: FB Barrels | X16: FB Barrel % | Y16: FB Chases | Z16: FB Chase % | AA16: FB Whiffs | AB16: FB Whiff % | AC16: Tot CB/SL | AD16: CB/SL Barrels | AE16: CB/SL Barrel % | AF16: CB/SL Chases | AG16: CB/SL Chase % | AH16: CB/SL Whiffs | AI16: CB/SL Whiff % | AJ16: Tot CH/SP | AK16: CH/SP Barrels | AL16: CH/SP Barrel % | AM16: CH/SP Chases | AN16: CH/SP Chase % | AO16: CH/SP Whiffs | AP16: CH/SP Whiff %
C17: Michael Caranna | D17: 24 | E17: =D17-G17-K17 -> 18 | F17: 8 | G17: 3 | H17: 109 | I17: =F17/D17 -> 0.33333333 | J17: =G17/D17 -> 0.125 | K17: 3 | L17: =(H17-G17)/D17 -> 4.4166667 | N17: 59 | O17: 89.8 | P17: 89.8 | S17: =T17/U17 -> 0.44444444 | T17: 20 | U17: 45
C18: Michael Chang | D18: 36 | E18: =D18-G18-K18 -> 29 | F18: 13 | G18: 7 | H18: 168 | I18: =F18/D18 -> 0.36111111 | J18: =G18/D18 -> 0.19444444 | K18: 0 | L18: =(H18-G18)/D18 -> 4.4722222 | O18: 92.1 | P18: 92.9 | S18: =T18/U18 -> 0.45 | T18: 27 | U18: 60
C19: Ryan Han | D19: 28 | E19: =D19-G19-K19 -> 27 | F19: 4 | G19: 1 | H19: 93 | I19: =F19/D19 -> 0.14285714 | J19: =G19/D19 -> 0.035714286 | K19: 0 | L19: =(H19-G19)/D19 -> 3.2857143 | S19: =T19/U19 -> 0.28571429 | T19: 14 | U19: 49
C20: Caleb Koontz | D20: 28 | E20: =D20-G20-K20 -> 19 | F20: 8 | G20: 8 | H20: 168 | I20: =F20/D20 -> 0.28571429 | J20: =G20/D20 -> 0.28571429 | K20: 1 | L20: =(H20-G20)/D20 -> 5.7142857 | O20: 91.9 | P20: 93.7 | S20: =T20/U20 -> 0.31343284 | T20: 21 | U20: 67
C21: Jackson Orr | D21: 29 | E21: =D21-G21-K21 -> 26 | F21: 4 | G21: 3 | H21: 104 | I21: =F21/D21 -> 0.13793103 | J21: =G21/D21 -> 0.10344828 | K21: 0 | L21: =(H21-G21)/D21 -> 3.4827586 | O21: 91.8 | P21: 92.3 | S21: =T21/U21 -> 0.24561404 | T21: 14 | U21: 57
C22: Reagan Samples | D22: 29 | E22: =D22-G22-K22 -> 21 | F22: 2 | G22: 8 | H22: 143 | I22: =F22/D22 -> 0.068965517 | J22: =G22/D22 -> 0.27586207 | K22: 0 | L22: =(H22-G22)/D22 -> 4.6551724 | S22: =T22/U22 -> 0.2244898 | T22: 11 | U22: 49
C23: Easton Steck | D23: 42 | E23: =D23-G23-K23 -> 33 | F23: 14 | G23: 9 | H23: 205 | I23: =F23/D23 -> 0.33333333 | J23: =G23/D23 -> 0.21428571 | K23: 0 | L23: =(H23-G23)/D23 -> 4.6666667 | O23: 101 | P23: 101.8 | S23: =T23/U23 -> 0.37647059 | T23: 32 | U23: 85
C24: Carter Walsh | D24: 36 | E24: =D24-G24-K24 -> 25 | F24: 4 | G24: 10 | H24: 177 | I24: =F24/D24 -> 0.11111111 | J24: =G24/D24 -> 0.27777778 | K24: 1 | L24: =(H24-G24)/D24 -> 4.6388889 | O24: 95.7 | P24: 96.6 | S24: =T24/U24 -> 0.21917808 | T24: 16 | U24: 73
C25: Aidan Young | D25: 39 | E25: =D25-G25-K25 -> 33 | F25: 14 | G25: 4 | H25: 175 | I25: =F25/D25 -> 0.35897436 | J25: =G25/D25 -> 0.1025641 | K25: 2 | L25: =(H25-G25)/D25 -> 4.3846154 | O25: 98.2 | P25: 99.5 | S25: =T25/U25 -> 0.27536232 | T25: 19 | U25: 69
I26: =F26/D26 -> #DIV/0! | J26: =G26/D26 -> #DIV/0! | L26: =(H26-G26)/D26 -> #DIV/0! | S26: =T26/U26 -> #DIV/0!
I27: =F27/D27 -> #DIV/0! | J27: =G27/D27 -> #DIV/0! | L27: =(H27-G27)/D27 -> #DIV/0! | S27: =T27/U27 -> #DIV/0!
B28: TOTALS | D28: =SUM(D17:D27) -> 291 | E28: =SUM(E17:E27) -> 231 | F28: =SUM(F17:F27) -> 71 | G28: =SUM(G17:G27) -> 53 | H28: =SUM(H17:H27) -> 1342 | I28: =F28/D28 -> 0.24398625 | J28: =G28/D28 -> 0.18213058 | K28: =SUM(K17:K27) -> 7 | L28: =(H28-G28)/D28 -> 4.4295533 | O28: =AVERAGE(O17:O27) -> 94.357143 | P28: =AVERAGE(P17:P27) -> 95.228571 | S28: =T28/U28 -> 0.31407942 | T28: =SUM(T17:T27) -> 174 | U28: =SUM(U17:U27) -> 554

Sheet Craig
B1: Live AB Stats
B2: ANDREW CRAIG
B3: Date | C3: 46193 | D3: 46197 | E3: 46203 | F3: 46218 | G3: 46224
B4: Opponent | C4: Live BP | D4: Live AB | E4: Live AB | F4: Live AB | G4: Live AB
A5: General | B5: IP | C5: 1 | D5: 2 | E5: 2 | F5: 3 | G5: 3 | H5: 0 | I5: 0 | J5: 0 | K5: 0 | L5: 0 | M5: 0
B6: TP | C6: 16 | D6: 46 | E6: 45 | F6: 53 | G6: 61 | H6: 0 | I6: 0 | J6: 0 | K6: 0 | L6: 0 | M6: 0
B7: B | C7: 11 | D7: 29 | E7: 24 | F7: 28 | G7: 34 | H7: 0 | I7: 0 | J7: 0 | K7: 0 | L7: 0 | M7: 0
B8: S | C8: 5 | D8: 17 | E8: 21 | F8: 25 | G8: 27 | H8: 0 | I8: 0 | J8: 0 | K8: 0 | L8: 0 | M8: 0
B9: K% | C9: =C8/C6 -> 0.3125 | D9: =D8/D6 -> 0.36956522 | E9: =E8/E6 -> 0.46666667 | F9: =F8/F6 -> 0.47169811 | G9: =G8/G6 -> 0.44262295 | H9: =H8/H6 -> #DIV/0! | I9: =I8/I6 -> #DIV/0! | J9: =J8/J6 -> #DIV/0! | ... M9: =M8/M6 -> #DIV/0!
B10: P/IP | C10: =C6/C5 -> 16 | D10: =D6/D5 -> 23 | E10: =E6/E5 -> 22.5 | F10: =F6/F5 -> 17.666667 | G10: =G6/G5 -> 20.333333 | H10: =H6/H5 -> #DIV/0! | I10: =I6/I5 -> #DIV/0! | J10: =J6/J5 -> #DIV/0! | ... M10: =M6/M5 -> #DIV/0!
B11: P/PA | C11: =C6/C12 -> 5.3333333 | D11: =D6/D12 -> 4.1818182 | E11: =E6/E12 -> 4.5 | F11: =F6/F12 -> 3.7857143 | G11: =G6/G12 -> 4.3571429 | H11: =H6/H12 -> #DIV/0! | I11: =I6/I12 -> #DIV/0! | J11: =J6/J12 -> #DIV/0! | ... M11: =M6/M12 -> #DIV/0!
B12: BF | C12: 3 | D12: 11 | E12: 10 | F12: 14 | G12: 14 | H12: 0 | I12: 0 | J12: 0 | K12: 0 | L12: 0 | M12: 0
B13: H | C13: 0 | D13: 1 | E13: 2 | F13: 1 | G13: 4 | H13: 0 | I13: 0 | J13: 0 | K13: 0 | L13: 0 | M13: 0
B14: BB | C14: 1 | D14: 4 | E14: 2 | F14: 3 | G14: 6 | H14: 0 | I14: 0 | J14: 0 | K14: 0 | L14: 0 | M14: 0
B15: BB% | C15: =C14/C12 -> 0.33333333 | D15: =D14/D12 -> 0.36363636 | E15: =E14/E12 -> 0.2 | F15: =F14/F12 -> 0.21428571 | G15: =G14/G12 -> 0.42857143 | H15: =H14/H12 -> #DIV/0! | I15: =I14/I12 -> #DIV/0! | J15: =J14/J12 -> #DIV/0! | ... M15: =M14/M12 -> #DIV/0!
B16: BB/7 | C16: =(C14/C5)*7 -> 7 | D16: =(D14/D5)*7 -> 14 | E16: =(E14/E5)*7 -> 7 | F16: =(F14/F5)*7 -> 7 | G16: =(G14/G5)*7 -> 14 | H16: =(H14/H5)*7 -> #DIV/0! | I16: =(I14/I5)*7 -> #DIV/0! | J16: =(J14/J5)*7 -> #DIV/0! | ... M16: =(M14/M5)*7 -> #DIV/0!
B17: HBP | C17: 0 | D17: 0 | E17: 1 | F17: 1 | G17: 0 | H17: 0 | I17: 0 | J17: 0 | K17: 0 | L17: 0 | M17: 0
B18: WHIP | C18: =(C14+C13)/C5 -> 1 | D18: =(D14+D13)/D5 -> 2.5 | E18: =(E14+E13)/E5 -> 2 | F18: =(F14+F13)/F5 -> 1.3333333 | G18: =(G14+G13)/G5 -> 3.3333333 | H18: =(H14+H13)/H5 -> #DIV/0! | I18: =(I14+I13)/I5 -> #DIV/0! | J18: =(J14+J13)/J5 -> #DIV/0! | ... M18: =(M14+M13)/M5 -> #DIV/0!
B19: KS | C19: 0 | D19: 1 | E19: 3 | F19: 4 | G19: 1 | H19: 0 | I19: 0 | J19: 0 | K19: 0 | L19: 0 | M19: 0
B20: KL | C20: 0 | D20: 0 | E20: 0 | F20: 1 | G20: 0 | H20: 0 | I20: 0 | J20: 0 | K20: 0 | L20: 0 | M20: 0
B21: K/7 | C21: =((C19+C20)/C5)*7 -> 0 | D21: =((D19+D20)/D5)*7 -> 3.5 | E21: =((E19+E20)/E5)*7 -> 10.5 | F21: =((F19+F20)/F5)*7 -> 11.666667 | G21: =((G19+G20)/G5)*7 -> 2.3333333 | H21: =((H19+H20)/H5)*7 -> #DIV/0! | I21: =((I19+I20)/I5)*7 -> #DIV/0! | J21: =((J19+J20)/J5)*7 -> #DIV/0! | ... M21: =((M19+M20)/M5)*7 -> #DIV/0!
B22: K% | C22: =(C19+C20)/C12 -> 0 | D22: =(D19+D20)/D12 -> 0.090909091 | E22: =(E19+E20)/E12 -> 0.3 | F22: =(F19+F20)/F12 -> 0.35714286 | G22: =(G19+G20)/G12 -> 0.071428571 | H22: =(H19+H20)/H12 -> #DIV/0! | I22: =(I19+I20)/I12 -> #DIV/0! | J22: =(J19+J20)/J12 -> #DIV/0! | ... M22: =(M19+M20)/M12 -> #DIV/0!
B23: K/BB | C23: =(C19+C20)/C14 -> 0 | D23: =(D19+D20)/D14 -> 0.25 | E23: =(E19+E20)/E14 -> 1.5 | F23: =(F19+F20)/F14 -> 1.6666667 | G23: =(G19+G20)/G14 -> 0.16666667 | H23: =(H19+H20)/H14 -> #DIV/0! | I23: =(I19+I20)/I14 -> #DIV/0! | J23: =(J19+J20)/J14 -> #DIV/0! | ... M23: =(M19+M20)/M14 -> #DIV/0!
B24: K%-BB% | C24: =C22-C15 -> -0.33333333 | D24: =D22-D15 -> -0.27272727 | E24: =E22-E15 -> 0.1 | F24: =F22-F15 -> 0.14285714 | G24: =G22-G15 -> -0.35714286 | H24: =H22-H15 -> #DIV/0! | I24: =I22-I15 -> #DIV/0! | J24: =J22-J15 -> #DIV/0! | ... M24: =M22-M15 -> #DIV/0!
B25: BAA | C25: =C13/(C12-C14-C17) -> 0 | D25: =D13/(D12-D14-D17) -> 0.14285714 | E25: =E13/(E12-E14-E17) -> 0.28571429 | F25: =F13/(F12-F14-F17) -> 0.1 | G25: =G13/(G12-G14-G17) -> 0.5 | H25: =H13/(H12-H14-H17) -> #DIV/0! | I25: =I13/(I12-I14-I17) -> #DIV/0! | J25: =J13/(J12-J14-J17) -> #DIV/0! | ... M25: =M13/(M12-M14-M17) -> #DIV/0!
A26: Efficiency | B26: FPS | C26: 0 | D26: 3 | E26: 4 | F26: 6 | G26: 6 | H26: 0 | I26: 0 | J26: 0 | K26: 0 | L26: 0 | M26: 0
B27: FPS% | C27: =C26/C12 -> 0 | D27: =D26/D12 -> 0.27272727 | E27: =E26/E12 -> 0.4 | F27: =F26/F12 -> 0.42857143 | G27: =G26/G12 -> 0.42857143 | H27: =H26/H12 -> #DIV/0! | I27: =I26/I12 -> #DIV/0! | J27: =J26/J12 -> #DIV/0! | ... M27: =M26/M12 -> #DIV/0!
B28: 2/3K | C28: 0 | D28: 1 | E28: 3 | F28: 2 | G28: 2 | H28: 0 | I28: 0 | J28: 0 | K28: 0 | L28: 0 | M28: 0
B29: 2/3K% | C29: =C28/C12 -> 0 | D29: =D28/D12 -> 0.090909091 | E29: =E28/E12 -> 0.3 | F29: =F28/F12 -> 0.14285714 | G29: =G28/G12 -> 0.14285714 | H29: =H28/H12 -> #DIV/0! | I29: =I28/I12 -> #DIV/0! | J29: =J28/J12 -> #DIV/0! | ... M29: =M28/M12 -> #DIV/0!
B30: <3P | C30: 0 | D30: 3 | E30: 4 | F30: 4 | G30: 5 | H30: 0 | I30: 0 | J30: 0 | K30: 0 | L30: 0 | M30: 0
B31: <3P% | C31: =C30/C12 -> 0 | D31: =D30/D12 -> 0.27272727 | E31: =E30/E12 -> 0.4 | F31: =F30/F12 -> 0.28571429 | G31: =G30/G12 -> 0.35714286 | H31: =H30/H12 -> #DIV/0! | I31: =I30/I12 -> #DIV/0! | J31: =J30/J12 -> #DIV/0! | ... M31: =M30/M12 -> #DIV/0!
B32: 3BC | C32: 2 | D32: 5 | E32: 5 | F32: 4 | G32: 6 | H32: 0 | I32: 0 | J32: 0 | K32: 0 | L32: 0 | M32: 0
B33: 3BC% | C33: =C32/C12 -> 0.66666667 | D33: =D32/D12 -> 0.45454545 | E33: =E32/E12 -> 0.5 | F33: =F32/F12 -> 0.28571429 | G33: =G32/G12 -> 0.42857143 | H33: =H32/H12 -> #DIV/0! | I33: =I32/I12 -> #DIV/0! | J33: =J32/J12 -> #DIV/0! | ... M33: =M32/M12 -> #DIV/0!
A34: Usages/Strike Percentages | B34: TFB | C34: 7 | D34: 32 | E34: 25 | F34: 18 | G34: 26 | H34: 0 | I34: 0 | J34: 0 | K34: 0 | L34: 0 | M34: 0
B35: FBK | C35: 2 | D35: 11 | E35: =SUMIF(F149:F193,"FB",I149:I193) -> 0 | F35: 6 | G35: 12 | H35: 0 | I35: 0 | J35: 0 | K35: 0 | L35: 0 | M35: 0
B36: FB% | C36: =C34/C6 -> 0.4375 | D36: =D34/D6 -> 0.69565217 | E36: =E34/E6 -> 0.55555556 | F36: =F34/F6 -> 0.33962264 | G36: =G34/G6 -> 0.42622951 | H36: =H34/H6 -> #DIV/0! | I36: =I34/I6 -> #DIV/0! | J36: =J34/J6 -> #DIV/0! | ... M36: =M34/M6 -> #DIV/0!
B37: FBK% | C37: =C35/C34 -> 0.28571429 | D37: =D35/D34 -> 0.34375 | E37: =E35/E34 -> 0 | F37: =F35/F34 -> 0.33333333 | G37: =G35/G34 -> 0.46153846 | H37: =H35/H34 -> #DIV/0! | I37: =I35/I34 -> #DIV/0! | J37: =J35/J34 -> #DIV/0! | ... M37: =M35/M34 -> #DIV/0!
B38: TCB | C38: 0 | D38: 0 | E38: 0 | F38: 0 | G38: 0 | H38: 0 | I38: 0 | J38: 0 | K38: 0 | L38: 0 | M38: 0
B39: CBK | C39: 0 | D39: 0 | E39: =SUMIF(F149:F193,"CB",I149:I193) -> 0 | F39: 0 | G39: 0 | H39: 0 | I39: 0 | J39: 0 | K39: 0 | L39: 0 | M39: 0
B40: CB% | C40: =C38/C6 -> 0 | D40: =D38/D6 -> 0 | E40: =E38/E6 -> 0 | F40: =F38/F6 -> 0 | G40: =G38/G6 -> 0 | H40: =H38/H6 -> #DIV/0! | I40: =I38/I6 -> #DIV/0! | J40: =J38/J6 -> #DIV/0! | ... M40: =M38/M6 -> #DIV/0!
...

Sheet Esteban
B1: Live AB Stats
B2: GABRIEL ESTEBAN
B3: Date | C3: 46193 | D3: 46200 | E3: 46214 | F3: 46221 | G3: 46224 | H3: 46228 | K3: Totals
B4: Opponent | C4: Live AB | D4: Live AB | E4: Live AB | F4: Live AB | G4: Velo | H4: Live AB
A5: General | B5: IP | C5: 2 | D5: 1.6666667 | E5: 3 | F5: 3 | G5: 0 | H5: 2.6666667 | I5: 0 | J5: 0 | K5: 0 | L5: 0 | M5: 0
B6: TP | C6: 40 | D6: 54 | E6: 68 | F6: 71 | G6: 19 | H6: 67 | I6: 0 | J6: 0 | K6: 0 | L6: 0 | M6: 0
B7: B | C7: 20 | D7: 23 | E7: 31 | F7: 36 | G7: 0 | H7: 33 | I7: 0 | J7: 0 | K7: 0 | L7: 0 | M7: 0
B8: S | C8: 20 | D8: 31 | E8: 37 | F8: 35 | G8: 19 | H8: 34 | I8: 0 | J8: 0 | K8: 0 | L8: 0 | M8: 0
B9: K% | C9: =C8/C6 -> 0.5 | D9: =D8/D6 -> 0.57407407 | E9: =E8/E6 -> 0.54411765 | F9: =F8/F6 -> 0.49295775 | G9: =G8/G6 -> 1 | H9: =H8/H6 -> 0.50746269 | I9: =I8/I6 -> #DIV/0! | J9: =J8/J6 -> #DIV/0! | ... M9: =M8/M6 -> #DIV/0!
B10: P/IP | C10: =C6/C5 -> 20 | D10: =D6/D5 -> 32.4 | E10: =E6/E5 -> 22.666667 | F10: =F6/F5 -> 23.666667 | G10: =G6/G5 -> #DIV/0! | H10: =H6/H5 -> 25.125 | I10: =I6/I5 -> #DIV/0! | J10: =J6/J5 -> #DIV/0! | ... M10: =M6/M5 -> #DIV/0!
B11: P/PA | C11: =C6/C12 -> 4.4444444 | D11: =D6/D12 -> 5.4 | E11: =E6/E12 -> 4.5333333 | F11: =F6/F12 -> 3.9444444 | G11: =G6/G12 -> #DIV/0! | H11: =H6/H12 -> 4.4666667 | I11: =I6/I12 -> #DIV/0! | J11: =J6/J12 -> #DIV/0! | ... M11: =M6/M12 -> #DIV/0!
B12: BF | C12: 9 | D12: 10 | E12: 15 | F12: 18 | G12: 0 | H12: 15 | I12: 0 | J12: 0 | K12: 0 | L12: 0 | M12: 0
B13: H | C13: 0 | D13: 2 | E13: 2 | F13: 6 | G13: 0 | H13: 3 | I13: 0 | J13: 0 | K13: 0 | L13: 0 | M13: 0
B14: BB | C14: 1 | D14: 3 | E14: 2 | F14: 2 | G14: 0 | H14: 5 | I14: 0 | J14: 0 | K14: 0 | L14: 0 | M14: 0
B15: BB% | C15: =C14/C12 -> 0.11111111 | D15: =D14/D12 -> 0.3 | E15: =E14/E12 -> 0.13333333 | F15: =F14/F12 -> 0.11111111 | G15: =G14/G12 -> #DIV/0! | H15: =H14/H12 -> 0.33333333 | I15: =I14/I12 -> #DIV/0! | J15: =J14/J12 -> #DIV/0! | ... M15: =M14/M12 -> #DIV/0!
B16: BB/7 | C16: =(C14/C5)*7 -> 3.5 | D16: =(D14/D5)*7 -> 12.6 | E16: =(E14/E5)*7 -> 4.6666667 | F16: =(F14/F5)*7 -> 4.6666667 | G16: =(G14/G5)*7 -> #DIV/0! | H16: =(H14/H5)*7 -> 13.125 | I16: =(I14/I5)*7 -> #DIV/0! | J16: =(J14/J5)*7 -> #DIV/0! | ... M16: =(M14/M5)*7 -> #DIV/0!
B17: HBP | C17: 2 | D17: 0 | E17: 0 | F17: 0 | G17: 0 | H17: 0 | I17: 0 | J17: 0 | K17: 0 | L17: 0 | M17: 0
B18: WHIP | C18: =(C14+C13)/C5 -> 0.5 | D18: =(D14+D13)/D5 -> 3 | E18: =(E14+E13)/E5 -> 1.3333333 | F18: =(F14+F13)/F5 -> 2.6666667 | G18: =(G14+G13)/G5 -> #DIV/0! | H18: =(H14+H13)/H5 -> 3 | I18: =(I14+I13)/I5 -> #DIV/0! | J18: =(J14+J13)/J5 -> #DIV/0! | ... M18: =(M14+M13)/M5 -> #DIV/0!
B19: KS | C19: 0 | D19: 0 | E19: 4 | F19: 3 | G19: 0 | H19: 1 | I19: 0 | J19: 0 | K19: 0 | L19: 0 | M19: 0
B20: KL | C20: 2 | D20: 0 | E20: 2 | F20: 0 | G20: 0 | H20: 2 | I20: 0 | J20: 0 | K20: 0 | L20: 0 | M20: 0
B21: K/7 | C21: =((C19+C20)/C5)*7 -> 7 | D21: =((D19+D20)/D5)*7 -> 0 | E21: =((E19+E20)/E5)*7 -> 14 | F21: =((F19+F20)/F5)*7 -> 7 | G21: =((G19+G20)/G5)*7 -> #DIV/0! | H21: =((H19+H20)/H5)*7 -> 7.875 | I21: =((I19+I20)/I5)*7 -> #DIV/0! | J21: =((J19+J20)/J5)*7 -> #DIV/0! | ... M21: =((M19+M20)/M5)*7 -> #DIV/0!
B22: K% | C22: =(C19+C20)/C12 -> 0.22222222 | D22: =(D19+D20)/D12 -> 0 | E22: =(E19+E20)/E12 -> 0.4 | F22: =(F19+F20)/F12 -> 0.16666667 | G22: =(G19+G20)/G12 -> #DIV/0! | H22: =(H19+H20)/H12 -> 0.2 | I22: =(I19+I20)/I12 -> #DIV/0! | J22: =(J19+J20)/J12 -> #DIV/0! | ... M22: =(M19+M20)/M12 -> #DIV/0!
B23: K/BB | C23: =(C19+C20)/C14 -> 2 | D23: =(D19+D20)/D14 -> 0 | E23: =(E19+E20)/E14 -> 3 | F23: =(F19+F20)/F14 -> 1.5 | G23: =(G19+G20)/G14 -> #DIV/0! | H23: =(H19+H20)/H14 -> 0.6 | I23: =(I19+I20)/I14 -> #DIV/0! | J23: =(J19+J20)/J14 -> #DIV/0! | ... M23: =(M19+M20)/M14 -> #DIV/0!
B24: K%-BB% | C24: =C22-C15 -> 0.11111111 | D24: =D22-D15 -> -0.3 | E24: =E22-E15 -> 0.26666667 | F24: =F22-F15 -> 0.055555556 | G24: =G22-G15 -> #DIV/0! | H24: =H22-H15 -> -0.13333333 | I24: =I22-I15 -> #DIV/0! | J24: =J22-J15 -> #DIV/0! | ... M24: =M22-M15 -> #DIV/0!
B25: BAA | C25: =C13/(C12-C14-C17) -> 0 | D25: =D13/(D12-D14-D17) -> 0.28571429 | E25: =E13/(E12-E14-E17) -> 0.15384615 | F25: =F13/(F12-F14-F17) -> 0.375 | G25: =G13/(G12-G14-G17) -> #DIV/0! | H25: =H13/(H12-H14-H17) -> 0.3 | I25: =I13/(I12-I14-I17) -> #DIV/0! | J25: =J13/(J12-J14-J17) -> #DIV/0! | ... M25: =M13/(M12-M14-M17) -> #DIV/0!
A26: Efficiency | B26: FPS | C26: 4 | D26: 1 | E26: 6 | F26: 6 | G26: 0 | H26: 6 | I26: 0 | J26: 0 | K26: 0 | L26: 0 | M26: 0
B27: FPS% | C27: =C26/C12 -> 0.44444444 | D27: =D26/D12 -> 0.1 | E27: =E26/E12 -> 0.4 | F27: =F26/F12 -> 0.33333333 | G27: =G26/G12 -> #DIV/0! | H27: =H26/H12 -> 0.4 | I27: =I26/I12 -> #DIV/0! | J27: =J26/J12 -> #DIV/0! | ... M27: =M26/M12 -> #DIV/0!
B28: 2/3K | C28: 3 | D28: 6 | E28: 6 | F28: 2 | G28: 0 | H28: 6 | I28: 0 | J28: 0 | K28: 0 | L28: 0 | M28: 0
B29: 2/3K% | C29: =C28/C12 -> 0.33333333 | D29: =D28/D12 -> 0.6 | E29: =E28/E12 -> 0.4 | F29: =F28/F12 -> 0.11111111 | G29: =G28/G12 -> #DIV/0! | H29: =H28/H12 -> 0.4 | I29: =I28/I12 -> #DIV/0! | J29: =J28/J12 -> #DIV/0! | ... M29: =M28/M12 -> #DIV/0!
B30: <3P | C30: 3 | D30: 3 | E30: 2 | F30: 6 | G30: 0 | H30: 3 | I30: 0 | J30: 0 | K30: 0 | L30: 0 | M30: 0
B31: <3P% | C31: =C30/C12 -> 0.33333333 | D31: =D30/D12 -> 0.3 | E31: =E30/E12 -> 0.13333333 | F31: =F30/F12 -> 0.33333333 | G31: =G30/G12 -> #DIV/0! | H31: =H30/H12 -> 0.2 | I31: =I30/I12 -> #DIV/0! | J31: =J30/J12 -> #DIV/0! | ... M31: =M30/M12 -> #DIV/0!
B32: 3BC | C32: 2 | D32: 3 | E32: 8 | F32: 10 | G32: 0 | H32: 6 | I32: 0 | J32: 0 | K32: 0 | L32: 0 | M32: 0
B33: 3BC% | C33: =C32/C12 -> 0.22222222 | D33: =D32/D12 -> 0.3 | E33: =E32/E12 -> 0.53333333 | F33: =F32/F12 -> 0.55555556 | G33: =G32/G12 -> #DIV/0! | H33: =H32/H12 -> 0.4 | I33: =I32/I12 -> #DIV/0! | J33: =J32/J12 -> #DIV/0! | ... M33: =M32/M12 -> #DIV/0!
A34: Usages/Strike Percentages | B34: TFB | C34: 22 | D34: 18 | E34: 27 | F34: 33 | G34: 0 | H34: 27 | I34: 0 | J34: 0 | K34: 0 | L34: 0 | M34: 0
B35: FBK | C35: 10 | D35: 10 | E35: 18 | F35: 22 | G35: 0 | H35: 16 | I35: 0 | J35: 0 | K35: 0 | L35: 0 | M35: 0
B36: FB% | C36: =C34/C6 -> 0.55 | D36: =D34/D6 -> 0.33333333 | E36: =E34/E6 -> 0.39705882 | F36: =F34/F6 -> 0.46478873 | G36: =G34/G6 -> 0 | H36: =H34/H6 -> 0.40298507 | I36: =I34/I6 -> #DIV/0! | J36: =J34/J6 -> #DIV/0! | ... M36: =M34/M6 -> #DIV/0!
B37: FBK% | C37: =C35/C34 -> 0.45454545 | D37: =D35/D34 -> 0.55555556 | E37: =E35/E34 -> 0.66666667 | F37: =F35/F34 -> 0.66666667 | G37: =G35/G34 -> #DIV/0! | H37: =H35/H34 -> 0.59259259 | I37: =I35/I34 -> #DIV/0! | J37: =J35/J34 -> #DIV/0! | ... M37: =M35/M34 -> #DIV/0!
B38: TSL | C38: 12 | D38: 26 | E38: 26 | F38: 15 | G38: 0 | H38: 24 | I38: 0 | J38: 0 | K38: 0 | L38: 0 | M38: 0
B39: SLK | C39: 7 | D39: 13 | E39: 11 | F39: 5 | G39: 0 | H39: 12 | I39: 0 | J39: 0 | K39: 0 | L39: 0 | M39: 0
B40: SL% | C40: =C38/C6 -> 0.3 | D40: =D38/D6 -> 0.48148148 | E40: =E38/E6 -> 0.38235294 | F40: =F38/F6 -> 0.21126761 | G40: =G38/G6 -> 0 | H40: =H38/H6 -> 0.35820896 | I40: =I38/I6 -> #DIV/0! | J40: =J38/J6 -> #DIV/0! | ... M40: =M38/M6 -> #DIV/0!
...

Sheet Garcia
B1: Live AB Stats
B2: SEBASTIAN GARCIA
B3: Date | C3: 46193 | D3: 46197 | E3: 46200 | F3: 46203 | G3: 46214 | H3: 46218 | I3: 46224 | J3: 46228 | K3: Totals
B4: Opponent | C4: Live BP | D4: Live AB | E4: Live BP | F4: Live AB | G4: Live AB | H4: Live AB | I4: Live AB | J4: Live AB
A5: General | B5: IP | C5: 1 | D5: 2 | E5: =5/3 -> 1.6666667 | F5: =5/3 -> 1.6666667 | G5: 2 | H5: =7/3 -> 2.3333333 | I5: 3 | J5: =4/3 -> 1.3333333 | K5: 0 | L5: 0 | M5: 0
B6: TP | C6: 23 | D6: 52 | E6: 26 | F6: 35 | G6: 29 | H6: 46 | I6: 58 | J6: 19 | K6: 0 | L6: 0 | M6: 0
B7: B | C7: 9 | D7: 24 | E7: 11 | F7: 15 | G7: 10 | H7: 21 | I7: 19 | J7: 8 | K7: 0 | L7: 0 | M7: 0
B8: S | C8: 14 | D8: 28 | E8: 15 | F8: 20 | G8: 19 | H8: 25 | I8: 39 | J8: 11 | K8: 0 | L8: 0 | M8: 0
B9: K% | C9: =C8/C6 -> 0.60869565 | D9: =D8/D6 -> 0.53846154 | E9: =E8/E6 -> 0.57692308 | F9: =F8/F6 -> 0.57142857 | G9: =G8/G6 -> 0.65517241 | H9: =H8/H6 -> 0.54347826 | I9: =I8/I6 -> 0.67241379 | J9: =J8/J6 -> 0.57894737 | ... M9: =M8/M6 -> #DIV/0!
B10: P/IP | C10: =C6/C5 -> 23 | D10: =D6/D5 -> 26 | E10: =E6/E5 -> 15.6 | F10: =F6/F5 -> 21 | G10: =G6/G5 -> 14.5 | H10: =H6/H5 -> 19.714286 | I10: =I6/I5 -> 19.333333 | J10: =J6/J5 -> 14.25 | ... M10: =M6/M5 -> #DIV/0!
B11: P/PA | C11: =C6/C12 -> 5.75 | D11: =D6/D12 -> 4.7272727 | E11: =E6/E12 -> 5.2 | F11: =F6/F12 -> 4.375 | G11: =G6/G12 -> 3.2222222 | H11: =H6/H12 -> 4.6 | I11: =I6/I12 -> 3.8666667 | J11: =J6/J12 -> 3.8 | ... M11: =M6/M12 -> #DIV/0!
B12: BF | C12: 4 | D12: 11 | E12: 5 | F12: 8 | G12: 9 | H12: 10 | I12: 15 | J12: 5 | K12: 0 | L12: 0 | M12: 0
B13: H | C13: 1 | D13: 0 | E13: 0 | F13: 2 | G13: 2 | H13: 1 | I13: 4 | J13: 1 | K13: 0 | L13: 0 | M13: 0
B14: BB | C14: 1 | D14: 5 | E14: 0 | F14: 1 | G14: 1 | H14: 2 | I14: 1 | J14: 0 | K14: 0 | L14: 0 | M14: 0
B15: BB% | C15: =C14/C12 -> 0.25 | D15: =D14/D12 -> 0.45454545 | E15: =E14/E12 -> 0 | F15: =F14/F12 -> 0.125 | G15: =G14/G12 -> 0.11111111 | H15: =H14/H12 -> 0.2 | I15: =I14/I12 -> 0.066666667 | J15: =J14/J12 -> 0 | ... M15: =M14/M12 -> #DIV/0!
B16: BB/7 | C16: =(C14/C5)*7 -> 7 | D16: =(D14/D5)*7 -> 17.5 | E16: =(E14/E5)*7 -> 0 | F16: =(F14/F5)*7 -> 4.2 | G16: =(G14/G5)*7 -> 3.5 | H16: =(H14/H5)*7 -> 6 | I16: =(I14/I5)*7 -> 2.3333333 | J16: =(J14/J5)*7 -> 0 | ... M16: =(M14/M5)*7 -> #DIV/0!
B17: HBP | C17: 0 | D17: 0 | E17: 0 | F17: 0 | G17: 0 | H17: 0 | I17: 0 | J17: 0 | K17: 0 | L17: 0 | M17: 0
B18: WHIP | C18: =(C14+C13)/C5 -> 2 | D18: =(D14+D13)/D5 -> 2.5 | E18: =(E14+E13)/E5 -> 0 | F18: =(F14+F13)/F5 -> 1.8 | G18: =(G14+G13)/G5 -> 1.5 | H18: =(H14+H13)/H5 -> 1.2857143 | I18: =(I14+I13)/I5 -> 1.6666667 | J18: =(J14+J13)/J5 -> 0.75 | ... M18: =(M14+M13)/M5 -> #DIV/0!
B19: KS | C19: 1 | D19: 1 | E19: 1 | F19: 2 | G19: 4 | H19: 2 | I19: 4 | J19: 0 | K19: 0 | L19: 0 | M19: 0
B20: KL | C20: 0 | D20: 0 | E20: 0 | F20: 0 | G20: 1 | H20: 2 | I20: 2 | J20: 2 | K20: 0 | L20: 0 | M20: 0
B21: K/7 | C21: =((C19+C20)/C5)*7 -> 7 | D21: =((D19+D20)/D5)*7 -> 3.5 | E21: =((E19+E20)/E5)*7 -> 4.2 | F21: =((F19+F20)/F5)*7 -> 8.4 | G21: =((G19+G20)/G5)*7 -> 17.5 | H21: =((H19+H20)/H5)*7 -> 12 | I21: =((I19+I20)/I5)*7 -> 14 | J21: =((J19+J20)/J5)*7 -> 10.5 | ... M21: =((M19+M20)/M5)*7 -> #DIV/0!
B22: K% | C22: =(C19+C20)/C12 -> 0.25 | D22: =(D19+D20)/D12 -> 0.090909091 | E22: =(E19+E20)/E12 -> 0.2 | F22: =(F19+F20)/F12 -> 0.25 | G22: =(G19+G20)/G12 -> 0.55555556 | H22: =(H19+H20)/H12 -> 0.4 | I22: =(I19+I20)/I12 -> 0.4 | J22: =(J19+J20)/J12 -> 0.4 | ... M22: =(M19+M20)/M12 -> #DIV/0!
B23: K/BB | C23: =(C19+C20)/C14 -> 1 | D23: =(D19+D20)/D14 -> 0.2 | E23: =(E19+E20)/E14 -> #DIV/0! | F23: =(F19+F20)/F14 -> 2 | G23: =(G19+G20)/G14 -> 5 | H23: =(H19+H20)/H14 -> 2 | I23: =(I19+I20)/I14 -> 6 | J23: =(J19+J20)/J14 -> #DIV/0! | ... M23: =(M19+M20)/M14 -> #DIV/0!
B24: K%-BB% | C24: =C22-C15 -> 0 | D24: =D22-D15 -> -0.36363636 | E24: =E22-E15 -> 0.2 | F24: =F22-F15 -> 0.125 | G24: =G22-G15 -> 0.44444444 | H24: =H22-H15 -> 0.2 | I24: =I22-I15 -> 0.33333333 | J24: =J22-J15 -> 0.4 | ... M24: =M22-M15 -> #DIV/0!
B25: BAA | C25: =C13/(C12-C14-C17) -> 0.33333333 | D25: =D13/(D12-D14-D17) -> 0 | E25: =E13/(E12-E14-E17) -> 0 | F25: =F13/(F12-F14-F17) -> 0.28571429 | G25: =G13/(G12-G14-G17) -> 0.25 | H25: =H13/(H12-H14-H17) -> 0.125 | I25: =I13/(I12-I14-I17) -> 0.28571429 | J25: =J13/(J12-J14-J17) -> 0.2 | ... M25: =M13/(M12-M14-M17) -> #DIV/0!
A26: Efficiency | B26: FPS | C26: 1 | D26: 6 | E26: 2 | F26: 3 | G26: 8 | H26: 5 | I26: 10 | J26: 1 | K26: 0 | L26: 0 | M26: 0
B27: FPS% | C27: =C26/C12 -> 0.25 | D27: =D26/D12 -> 0.54545455 | E27: =E26/E12 -> 0.4 | F27: =F26/F12 -> 0.375 | G27: =G26/G12 -> 0.88888889 | H27: =H26/H12 -> 0.5 | I27: =I26/I12 -> 0.66666667 | J27: =J26/J12 -> 0.2 | ... M27: =M26/M12 -> #DIV/0!
B28: 2/3K | C28: 2 | D28: 5 | E28: 1 | F28: 2 | G28: 5 | H28: 6 | I28: 9 | J28: 2 | K28: 0 | L28: 0 | M28: 0
B29: 2/3K% | C29: =C28/C12 -> 0.5 | D29: =D28/D12 -> 0.45454545 | E29: =E28/E12 -> 0.2 | F29: =F28/F12 -> 0.25 | G29: =G28/G12 -> 0.55555556 | H29: =H28/H12 -> 0.6 | I29: =I28/I12 -> 0.6 | J29: =J28/J12 -> 0.4 | ... M29: =M28/M12 -> #DIV/0!
B30: <3P | C30: 0 | D30: 4 | E30: 0 | F30: 4 | G30: 5 | H30: 3 | I30: 8 | J30: 2 | K30: 0 | L30: 0 | M30: 0
B31: <3P% | C31: =C30/C12 -> 0 | D31: =D30/D12 -> 0.36363636 | E31: =E30/E12 -> 0 | F31: =F30/F12 -> 0.5 | G31: =G30/G12 -> 0.55555556 | H31: =H30/H12 -> 0.3 | I31: =I30/I12 -> 0.53333333 | J31: =J30/J12 -> 0.4 | ... M31: =M30/M12 -> #DIV/0!
B32: 3BC | C32: 1 | D32: 5 | E32: 1 | F32: 3 | G32: 1 | H32: 4 | I32: 1 | J32: 1 | K32: 0 | L32: 0 | M32: 0
B33: 3BC% | C33: =C32/C12 -> 0.25 | D33: =D32/D12 -> 0.45454545 | E33: =E32/E12 -> 0.2 | F33: =F32/F12 -> 0.375 | G33: =G32/G12 -> 0.11111111 | H33: =H32/H12 -> 0.4 | I33: =I32/I12 -> 0.066666667 | J33: =J32/J12 -> 0.2 | ... M33: =M32/M12 -> #DIV/0!
A34: Usages/Strike Percentages | B34: TFB | C34: 12 | D34: 36 | E34: 12 | F34: 18 | G34: 17 | H34: 23 | I34: 27 | J34: 11 | K34: 0 | L34: 0 | M34: 0
B35: FBK | C35: 7 | D35: 22 | E35: 8 | F35: 9 | G35: 11 | H35: 13 | I35: 18 | J35: 9 | K35: 0 | L35: 0 | M35: 0
B36: FB% | C36: =C34/C6 -> 0.52173913 | D36: =D34/D6 -> 0.69230769 | E36: =E34/E6 -> 0.46153846 | F36: =F34/F6 -> 0.51428571 | G36: =G34/G6 -> 0.5862069 | H36: =H34/H6 -> 0.5 | I36: =I34/I6 -> 0.46551724 | J36: =J34/J6 -> 0.57894737 | ... M36: =M34/M6 -> #DIV/0!
B37: FBK% | C37: =C35/C34 -> 0.58333333 | D37: =D35/D34 -> 0.61111111 | E37: =E35/E34 -> 0.66666667 | F37: =F35/F34 -> 0.5 | G37: =G35/G34 -> 0.64705882 | H37: =H35/H34 -> 0.56521739 | I37: =I35/I34 -> 0.66666667 | J37: =J35/J34 -> 0.81818182 | ... M37: =M35/M34 -> #DIV/0!
B38: TCB | C38: 0 | D38: 0 | E38: 0 | F38: 0 | G38: 0 | H38: 0 | I38: 0 | J38: 0 | K38: 0 | L38: 0 | M38: 0
B39: CBK | C39: 0 | D39: 0 | E39: 0 | F39: 0 | G39: 0 | H39: 0 | I39: 0 | J39: 0 | K39: 0 | L39: 0 | M39: 0
B40: CB% | C40: =C38/C6 -> 0 | D40: =D38/D6 -> 0 | E40: =E38/E6 -> 0 | F40: =F38/F6 -> 0 | G40: =G38/G6 -> 0 | H40: =H38/H6 -> 0 | I40: =I38/I6 -> 0 | J40: =J38/J6 -> 0 | ... M40: =M38/M6 -> #DIV/0!
...

Sheet Orr (P)
B1: Live AB Stats
B2: JACKSON ORR
B3: Date | C3: 46197 | D3: 46200 | E3: 46203 | F3: 46221 | G3: 46228
B4: Opponent | C4: Live AB | D4: Live BP | E4: Live AB | F4: Live AB | G4: Live AB
A5: General | B5: IP | C5: 1 | D5: 1.3333333 | E5: 2 | F5: =4/3 -> 1.3333333 | G5: 1 | H5: 0 | I5: 0 | J5: 0 | K5: 0 | L5: 0 | M5: 0
B6: TP | C6: 21 | D6: 26 | E6: 42 | F6: 44 | G6: 39 | H6: 0 | I6: 0 | J6: 0 | K6: 0 | L6: 0 | M6: 0
B7: B | C7: 9 | D7: 10 | E7: 21 | F7: 23 | G7: 22 | H7: 0 | I7: 0 | J7: 0 | K7: 0 | L7: 0 | M7: 0
B8: S | C8: 12 | D8: 16 | E8: 21 | F8: 18 | G8: 17 | H8: 0 | I8: 0 | J8: 0 | K8: 0 | L8: 0 | M8: 0
B9: K% | C9: =C8/C6 -> 0.57142857 | D9: =D8/D6 -> 0.61538462 | E9: =E8/E6 -> 0.5 | F9: =F8/F6 -> 0.40909091 | G9: =G8/G6 -> 0.43589744 | H9: =H8/H6 -> #DIV/0! | I9: =I8/I6 -> #DIV/0! | J9: =J8/J6 -> #DIV/0! | ... M9: =M8/M6 -> #DIV/0!
B10: P/IP | C10: =C6/C5 -> 21 | D10: =D6/D5 -> 19.5 | E10: =E6/E5 -> 21 | F10: =F6/F5 -> 33 | G10: =G6/G5 -> 39 | H10: =H6/H5 -> #DIV/0! | I10: =I6/I5 -> #DIV/0! | J10: =J6/J5 -> #DIV/0! | ... M10: =M6/M5 -> #DIV/0!
B11: P/PA | C11: =C6/C12 -> 4.2 | D11: =D6/D12 -> 5.2 | E11: =E6/E12 -> 3.8181818 | F11: =F6/F12 -> 5.5 | G11: =G6/G12 -> 5.5714286 | H11: =H6/H12 -> #DIV/0! | I11: =I6/I12 -> #DIV/0! | J11: =J6/J12 -> #DIV/0! | ... M11: =M6/M12 -> #DIV/0!
B12: BF | C12: 5 | D12: 5 | E12: 11 | F12: 8 | G12: 7 | H12: 0 | I12: 0 | J12: 0 | K12: 0 | L12: 0 | M12: 0
B13: H | C13: 2 | D13: 1 | E13: 3 | F13: 0 | G13: 1 | H13: 0 | I13: 0 | J13: 0 | K13: 0 | L13: 0 | M13: 0
B14: BB | C14: 0 | D14: 0 | E14: 2 | F14: 4 | G14: 4 | H14: 0 | I14: 0 | J14: 0 | K14: 0 | L14: 0 | M14: 0
B15: BB% | C15: =C14/C12 -> 0 | D15: =D14/D12 -> 0 | E15: =E14/E12 -> 0.18181818 | F15: =F14/F12 -> 0.5 | G15: =G14/G12 -> 0.57142857 | H15: =H14/H12 -> #DIV/0! | I15: =I14/I12 -> #DIV/0! | J15: =J14/J12 -> #DIV/0! | ... M15: =M14/M12 -> #DIV/0!
B16: BB/7 | C16: =(C14/C5)*7 -> 0 | D16: =(D14/D5)*7 -> 0 | E16: =(E14/E5)*7 -> 7 | F16: =(F14/F5)*7 -> 21 | G16: =(G14/G5)*7 -> 28 | H16: =(H14/H5)*7 -> #DIV/0! | I16: =(I14/I5)*7 -> #DIV/0! | J16: =(J14/J5)*7 -> #DIV/0! | ... M16: =(M14/M5)*7 -> #DIV/0!
B17: HBP | C17: 0 | D17: 0 | E17: 1 | F17: 0 | G17: 0 | H17: 0 | I17: 0 | J17: 0 | K17: 0 | L17: 0 | M17: 0
B18: WHIP | C18: =(C14+C13)/C5 -> 2 | D18: =(D14+D13)/D5 -> 0.75 | E18: =(E14+E13)/E5 -> 2.5 | F18: =(F14+F13)/F5 -> 3 | G18: =(G14+G13)/G5 -> 5 | H18: =(H14+H13)/H5 -> #DIV/0! | I18: =(I14+I13)/I5 -> #DIV/0! | J18: =(J14+J13)/J5 -> #DIV/0! | ... M18: =(M14+M13)/M5 -> #DIV/0!
B19: KS | C19: 1 | D19: 1 | E19: 3 | F19: 1 | G19: 0 | H19: 0 | I19: 0 | J19: 0 | K19: 0 | L19: 0 | M19: 0
B20: KL | C20: 0 | D20: 1 | E20: 1 | F20: 1 | G20: 1 | H20: 0 | I20: 0 | J20: 0 | K20: 0 | L20: 0 | M20: 0
B21: K/7 | C21: =((C19+C20)/C5)*7 -> 7 | D21: =((D19+D20)/D5)*7 -> 10.5 | E21: =((E19+E20)/E5)*7 -> 14 | F21: =((F19+F20)/F5)*7 -> 10.5 | G21: =((G19+G20)/G5)*7 -> 7 | H21: =((H19+H20)/H5)*7 -> #DIV/0! | I21: =((I19+I20)/I5)*7 -> #DIV/0! | J21: =((J19+J20)/J5)*7 -> #DIV/0! | ... M21: =((M19+M20)/M5)*7 -> #DIV/0!
B22: K% | C22: =(C19+C20)/C12 -> 0.2 | D22: =(D19+D20)/D12 -> 0.4 | E22: =(E19+E20)/E12 -> 0.36363636 | F22: =(F19+F20)/F12 -> 0.25 | G22: =(G19+G20)/G12 -> 0.14285714 | H22: =(H19+H20)/H12 -> #DIV/0! | I22: =(I19+I20)/I12 -> #DIV/0! | J22: =(J19+J20)/J12 -> #DIV/0! | ... M22: =(M19+M20)/M12 -> #DIV/0!
B23: K/BB | C23: =(C19+C20)/C14 -> #DIV/0! | D23: =(D19+D20)/D14 -> #DIV/0! | E23: =(E19+E20)/E14 -> 2 | F23: =(F19+F20)/F14 -> 0.5 | G23: =(G19+G20)/G14 -> 0.25 | H23: =(H19+H20)/H14 -> #DIV/0! | I23: =(I19+I20)/I14 -> #DIV/0! | J23: =(J19+J20)/J14 -> #DIV/0! | ... M23: =(M19+M20)/M14 -> #DIV/0!
B24: K%-BB% | C24: =C22-C15 -> 0.2 | D24: =D22-D15 -> 0.4 | E24: =E22-E15 -> 0.18181818 | F24: =F22-F15 -> -0.25 | G24: =G22-G15 -> -0.42857143 | H24: =H22-H15 -> #DIV/0! | I24: =I22-I15 -> #DIV/0! | J24: =J22-J15 -> #DIV/0! | ... M24: =M22-M15 -> #DIV/0!
B25: BAA | C25: =C13/(C12-C14-C17) -> 0.4 | D25: =D13/(D12-D14-D17) -> 0.2 | E25: =E13/(E12-E14-E17) -> 0.375 | F25: =F13/(F12-F14-F17) -> 0 | G25: =G13/(G12-G14-G17) -> 0.33333333 | H25: =H13/(H12-H14-H17) -> #DIV/0! | I25: =I13/(I12-I14-I17) -> #DIV/0! | J25: =J13/(J12-J14-J17) -> #DIV/0! | ... M25: =M13/(M12-M14-M17) -> #DIV/0!
A26: Efficiency | B26: FPS | C26: 4 | D26: 3 | E26: 3 | F26: 3 | G26: 3 | H26: 0 | I26: 0 | J26: 0 | K26: 0 | L26: 0 | M26: 0
B27: FPS% | C27: =C26/C12 -> 0.8 | D27: =D26/D12 -> 0.6 | E27: =E26/E12 -> 0.27272727 | F27: =F26/F12 -> 0.375 | G27: =G26/G12 -> 0.42857143 | H27: =H26/H12 -> #DIV/0! | I27: =I26/I12 -> #DIV/0! | J27: =J26/J12 -> #DIV/0! | ... M27: =M26/M12 -> #DIV/0!
B28: 2/3K | C28: 1 | D28: 4 | E28: 4 | F28: 1 | G28: 2 | H28: 0 | I28: 0 | J28: 0 | K28: 0 | L28: 0 | M28: 0
B29: 2/3K% | C29: =C28/C12 -> 0.2 | D29: =D28/D12 -> 0.8 | E29: =E28/E12 -> 0.36363636 | F29: =F28/F12 -> 0.125 | G29: =G28/G12 -> 0.28571429 | H29: =H28/H12 -> #DIV/0! | I29: =I28/I12 -> #DIV/0! | J29: =J28/J12 -> #DIV/0! | ... M29: =M28/M12 -> #DIV/0!
B30: <3P | C30: 2 | D30: 0 | E30: 6 | F30: 0 | G30: 1 | H30: 0 | I30: 0 | J30: 0 | K30: 0 | L30: 0 | M30: 0
B31: <3P% | C31: =C30/C12 -> 0.4 | D31: =D30/D12 -> 0 | E31: =E30/E12 -> 0.54545455 | F31: =F30/F12 -> 0 | G31: =G30/G12 -> 0.14285714 | H31: =H30/H12 -> #DIV/0! | I31: =I30/I12 -> #DIV/0! | J31: =J30/J12 -> #DIV/0! | ... M31: =M30/M12 -> #DIV/0!
B32: 3BC | C32: 2 | D32: 1 | E32: 3 | F32: 6 | G32: 5 | H32: 0 | I32: 0 | J32: 0 | K32: 0 | L32: 0 | M32: 0
B33: 3BC% | C33: =C32/C12 -> 0.4 | D33: =D32/D12 -> 0.2 | E33: =E32/E12 -> 0.27272727 | F33: =F32/F12 -> 0.75 | G33: =G32/G12 -> 0.71428571 | H33: =H32/H12 -> #DIV/0! | I33: =I32/I12 -> #DIV/0! | J33: =J32/J12 -> #DIV/0! | ... M33: =M32/M12 -> #DIV/0!
A34: Usages/Strike Percentages | B34: TFB | C34: 13 | D34: 16 | E34: 23 | F34: 27 | G34: 23 | H34: 0 | I34: 0 | J34: 0 | K34: 0 | L34: 0 | M34: 0
B35: FBK | C35: 11 | D35: 12 | E35: 12 | F35: 12 | G35: 11 | H35: 0 | I35: 0 | J35: 0 | K35: 0 | L35: 0 | M35: 0
B36: FB% | C36: =C34/C6 -> 0.61904762 | D36: =D34/D6 -> 0.61538462 | E36: =E34/E6 -> 0.54761905 | F36: =F34/F6 -> 0.61363636 | G36: =G34/G6 -> 0.58974359 | H36: =H34/H6 -> #DIV/0! | I36: =I34/I6 -> #DIV/0! | J36: =J34/J6 -> #DIV/0! | ... M36: =M34/M6 -> #DIV/0!
B37: FBK% | C37: =C35/C34 -> 0.84615385 | D37: =D35/D34 -> 0.75 | E37: =E35/E34 -> 0.52173913 | F37: =F35/F34 -> 0.44444444 | G37: =G35/G34 -> 0.47826087 | H37: =H35/H34 -> #DIV/0! | I37: =I35/I34 -> #DIV/0! | J37: =J35/J34 -> #DIV/0! | ... M37: =M35/M34 -> #DIV/0!
B38: TCB | C38: 2 | D38: 4 | E38: 5 | F38: 2 | G38: 5 | H38: 0 | I38: 0 | J38: 0 | K38: 0 | L38: 0 | M38: 0
B39: CBK | C39: 0 | D39: 1 | E39: 2 | F39: 1 | G39: 2 | H39: 0 | I39: 0 | J39: 0 | K39: 0 | L39: 0 | M39: 0
B40: CB% | C40: =C38/C6 -> 0.095238095 | D40: =D38/D6 -> 0.15384615 | E40: =E38/E6 -> 0.11904762 | F40: =F38/F6 -> 0.045454545 | G40: =G38/G6 -> 0.12820513 | H40: =H38/H6 -> #DIV/0! | I40: =I38/I6 -> #DIV/0! | J40: =J38/J6 -> #DIV/0! | ... M40: =M38/M6 -> #DIV/0!
...

Sheet Samples (P)
B1: Live AB Stats
B2: REAGAN SAMPLES
B3: Date | C3: 46193 | D3: 46200 | E3: 46214 | F3: 46221 | G3: 46228 | K3: Totals
B4: Opponent | C4: Live AB | D4: Live AB | E4: Live AB | F4: Live AB | G4: Live AB
A5: General | B5: IP | C5: 2 | D5: 4 | E5: 3 | F5: 3 | G5: 3 | H5: 0 | I5: 0 | J5: 0 | K5: 0 | L5: 0 | M5: 0
B6: TP | C6: 38 | D6: 56 | E6: 62 | F6: 48 | G6: 54 | H6: 0 | I6: 0 | J6: 0 | K6: 0 | L6: 0 | M6: 0
B7: B | C7: 16 | D7: 18 | E7: 25 | F7: 19 | G7: 27 | H7: 0 | I7: 0 | J7: 0 | K7: 0 | L7: 0 | M7: 0
B8: S | C8: 22 | D8: 38 | E8: 37 | F8: 29 | G8: 27 | H8: 0 | I8: 0 | J8: 0 | K8: 0 | L8: 0 | M8: 0
B9: K% | C9: =C8/C6 -> 0.57894737 | D9: =D8/D6 -> 0.67857143 | E9: =E8/E6 -> 0.59677419 | F9: =F8/F6 -> 0.60416667 | G9: =G8/G6 -> 0.5 | H9: =H8/H6 -> #DIV/0! | I9: =I8/I6 -> #DIV/0! | J9: =J8/J6 -> #DIV/0! | ... M9: =M8/M6 -> #DIV/0!
B10: P/IP | C10: =C6/C5 -> 19 | D10: =D6/D5 -> 14 | E10: =E6/E5 -> 20.666667 | F10: =F6/F5 -> 16 | G10: =G6/G5 -> 18 | H10: =H6/H5 -> #DIV/0! | I10: =I6/I5 -> #DIV/0! | J10: =J6/J5 -> #DIV/0! | ... M10: =M6/M5 -> #DIV/0!
B11: P/PA | C11: =C6/C12 -> 4.75 | D11: =D6/D12 -> 3.5 | E11: =E6/E12 -> 4.7692308 | F11: =F6/F12 -> 3.6923077 | G11: =G6/G12 -> 4.1538462 | H11: =H6/H12 -> #DIV/0! | I11: =I6/I12 -> #DIV/0! | J11: =J6/J12 -> #DIV/0! | ... M11: =M6/M12 -> #DIV/0!
B12: BF | C12: 8 | D12: 16 | E12: 13 | F12: 13 | G12: 13 | H12: 0 | I12: 0 | J12: 0 | K12: 0 | L12: 0 | M12: 0
B13: H | C13: 2 | D13: 3 | E13: 2 | F13: 3 | G13: 2 | H13: 0 | I13: 0 | J13: 0 | K13: 0 | L13: 0 | M13: 0
B14: BB | C14: 1 | D14: 0 | E14: 2 | F14: 1 | G14: 4 | H14: 0 | I14: 0 | J14: 0 | K14: 0 | L14: 0 | M14: 0
B15: BB% | C15: =C14/C12 -> 0.125 | D15: =D14/D12 -> 0 | E15: =E14/E12 -> 0.15384615 | F15: =F14/F12 -> 0.076923077 | G15: =G14/G12 -> 0.30769231 | H15: =H14/H12 -> #DIV/0! | I15: =I14/I12 -> #DIV/0! | J15: =J14/J12 -> #DIV/0! | ... M15: =M14/M12 -> #DIV/0!
B16: BB/7 | C16: =(C14/C5)*7 -> 3.5 | D16: =(D14/D5)*7 -> 0 | E16: =(E14/E5)*7 -> 4.6666667 | F16: =(F14/F5)*7 -> 2.3333333 | G16: =(G14/G5)*7 -> 9.3333333 | H16: =(H14/H5)*7 -> #DIV/0! | I16: =(I14/I5)*7 -> #DIV/0! | J16: =(J14/J5)*7 -> #DIV/0! | ... M16: =(M14/M5)*7 -> #DIV/0!
B17: HBP | C17: 0 | D17: 1 | E17: 0 | F17: 0 | G17: 0 | H17: 0 | I17: 0 | J17: 0 | K17: 0 | L17: 0 | M17: 0
B18: WHIP | C18: =(C14+C13)/C5 -> 1.5 | D18: =(D14+D13)/D5 -> 0.75 | E18: =(E14+E13)/E5 -> 1.3333333 | F18: =(F14+F13)/F5 -> 1.3333333 | G18: =(G14+G13)/G5 -> 2 | H18: =(H14+H13)/H5 -> #DIV/0! | I18: =(I14+I13)/I5 -> #DIV/0! | J18: =(J14+J13)/J5 -> #DIV/0! | ... M18: =(M14+M13)/M5 -> #DIV/0!
B19: KS | C19: 2 | D19: 5 | E19: 3 | F19: 2 | G19: 0 | H19: 0 | I19: 0 | J19: 0 | K19: 0 | L19: 0 | M19: 0
B20: KL | C20: 0 | D20: 0 | E20: 0 | F20: 1 | G20: 0 | H20: 0 | I20: 0 | J20: 0 | K20: 0 | L20: 0 | M20: 0
B21: K/7 | C21: =((C19+C20)/C5)*7 -> 7 | D21: =((D19+D20)/D5)*7 -> 8.75 | E21: =((E19+E20)/E5)*7 -> 7 | F21: =((F19+F20)/F5)*7 -> 7 | G21: =((G19+G20)/G5)*7 -> 0 | H21: =((H19+H20)/H5)*7 -> #DIV/0! | I21: =((I19+I20)/I5)*7 -> #DIV/0! | J21: =((J19+J20)/J5)*7 -> #DIV/0! | ... M21: =((M19+M20)/M5)*7 -> #DIV/0!
B22: K% | C22: =(C19+C20)/C12 -> 0.25 | D22: =(D19+D20)/D12 -> 0.3125 | E22: =(E19+E20)/E12 -> 0.23076923 | F22: =(F19+F20)/F12 -> 0.23076923 | G22: =(G19+G20)/G12 -> 0 | H22: =(H19+H20)/H12 -> #DIV/0! | I22: =(I19+I20)/I12 -> #DIV/0! | J22: =(J19+J20)/J12 -> #DIV/0! | ... M22: =(M19+M20)/M12 -> #DIV/0!
B23: K/BB | C23: =(C19+C20)/C14 -> 2 | D23: =(D19+D20)/D14 -> #DIV/0! | E23: =(E19+E20)/E14 -> 1.5 | F23: =(F19+F20)/F14 -> 3 | G23: =(G19+G20)/G14 -> 0 | H23: =(H19+H20)/H14 -> #DIV/0! | I23: =(I19+I20)/I14 -> #DIV/0! | J23: =(J19+J20)/J14 -> #DIV/0! | ... M23: =(M19+M20)/M14 -> #DIV/0!
B24: K%-BB% | C24: =C22-C15 -> 0.125 | D24: =D22-D15 -> 0.3125 | E24: =E22-E15 -> 0.076923077 | F24: =F22-F15 -> 0.15384615 | G24: =G22-G15 -> -0.30769231 | H24: =H22-H15 -> #DIV/0! | I24: =I22-I15 -> #DIV/0! | J24: =J22-J15 -> #DIV/0! | ... M24: =M22-M15 -> #DIV/0!
B25: BAA | C25: =C13/(C12-C14-C17) -> 0.28571429 | D25: =D13/(D12-D14-D17) -> 0.2 | E25: =E13/(E12-E14-E17) -> 0.18181818 | F25: =F13/(F12-F14-F17) -> 0.25 | G25: =G13/(G12-G14-G17) -> 0.22222222 | H25: =H13/(H12-H14-H17) -> #DIV/0! | I25: =I13/(I12-I14-I17) -> #DIV/0! | J25: =J13/(J12-J14-J17) -> #DIV/0! | ... M25: =M13/(M12-M14-M17) -> #DIV/0!
A26: Efficiency | B26: FPS | C26: 2 | D26: 12 | E26: 5 | F26: 8 | G26: 7 | H26: 0 | I26: 0 | J26: 0 | K26: 0 | L26: 0 | M26: 0
B27: FPS% | C27: =C26/C12 -> 0.25 | D27: =D26/D12 -> 0.75 | E27: =E26/E12 -> 0.38461538 | F27: =F26/F12 -> 0.61538462 | G27: =G26/G12 -> 0.53846154 | H27: =H26/H12 -> #DIV/0! | I27: =I26/I12 -> #DIV/0! | J27: =J26/J12 -> #DIV/0! | ... M27: =M26/M12 -> #DIV/0!
B28: 2/3K | C28: 5 | D28: 9 | E28: 8 | F28: 6 | G28: 5 | H28: 0 | I28: 0 | J28: 0 | K28: 0 | L28: 0 | M28: 0
B29: 2/3K% | C29: =C28/C12 -> 0.625 | D29: =D28/D12 -> 0.5625 | E29: =E28/E12 -> 0.61538462 | F29: =F28/F12 -> 0.46153846 | G29: =G28/G12 -> 0.38461538 | H29: =H28/H12 -> #DIV/0! | I29: =I28/I12 -> #DIV/0! | J29: =J28/J12 -> #DIV/0! | ... M29: =M28/M12 -> #DIV/0!
B30: <3P | C30: 2 | D30: 7 | E30: 4 | F30: 7 | G30: 5 | H30: 0 | I30: 0 | J30: 0 | K30: 0 | L30: 0 | M30: 0
B31: <3P% | C31: =C30/C12 -> 0.25 | D31: =D30/D12 -> 0.4375 | E31: =E30/E12 -> 0.30769231 | F31: =F30/F12 -> 0.53846154 | G31: =G30/G12 -> 0.38461538 | H31: =H30/H12 -> #DIV/0! | I31: =I30/I12 -> #DIV/0! | J31: =J30/J12 -> #DIV/0! | ... M31: =M30/M12 -> #DIV/0!
B32: 3BC | C32: 3 | D32: 3 | E32: 3 | F32: 4 | G32: 5 | H32: 0 | I32: 0 | J32: 0 | K32: 0 | L32: 0 | M32: 0
